Workbook

Sheet Summary
R1: Receiving | AY1: Secondary
M2: Opening | R2: 1 | S2: 2 | T2: 3 | U2: 4 | V2: 5 | W2: 6 | X2: 7 | Y2: 8 | Z2: 9 | AA2: 10 | AB2: 11 | AC2: 12 | AD2: 13 | AE2: 14 | AF2: 15 | AG2: 16 | AH2: 17 | AI2: 18 | AJ2: 19 | AK2: 20 | AL2: 21 | AM2: 22 | AN2: 23 | AO2: 24 | AP2: 25 | AQ2: 26 | AR2: 27 | AS2: 28 | AT2: 29 | AU2: 30 | AV2: 31 | AW2: Total | AY2: 1 | AZ2: 2 | BA2: 3 | BB2: 4 | BC2: 5 | BD2: 6 | BE2: 7 | BF2: 8 | BG2: 9 | BH2: 10 | BI2: 11 | BJ2: 12 | BK2: 13 | BL2: 14 | BM2: 15 | BN2: 16 | BO2: 17 | BP2: 18 | BQ2: 19 | BR2: 20 | BS2: 21 | BT2: 22 | BU2: 23 | BV2: 24 | BW2: 25 | BX2: 26 | BY2: 27 | BZ2: 28 | CA2: 29 | CB2: 30 | CC2: 31 | CD2: Total | CF2: Opening | CG2: Total Primary | CH2: Total | CI2: Total Secondary | CJ2: Closing
B3: Code | C3: Description | D3: Pack Size | E3: Pack Size | F3: List Price | H3: CTN | I3: BOX | J3: PCS | K3: Damage | M3: CTN | N3: CTN | O3: Total Box | P3: Amount | R3: CTN | S3: CTN | T3: CTN | U3: CTN | V3: CTN | W3: CTN | X3: CTN | Y3: CTN | Z3: CTN | AA3: CTN | AB3: CTN | AC3: CTN | AD3: CTN | AE3: CTN | AF3: CTN | AG3: CTN | AH3: CTN | AI3: CTN | AJ3: CTN | AK3: CTN | AL3: CTN | AM3: CTN | AN3: CTN | AO3: CTN | AP3: CTN | AQ3: CTN | AR3: CTN | AS3: CTN | AT3: CTN | AU3: CTN | AV3: CTN | AW3: CTN | AY3: CTN | AZ3: CTN | BA3: CTN | BB3: CTN | BC3: CTN | BD3: CTN | BE3: CTN | BF3: CTN | BG3: CTN | BH3: CTN | BI3: CTN | BJ3: CTN | BK3: CTN | BL3: CTN | BM3: CTN | BN3: CTN | BO3: CTN | BP3: CTN | BQ3: CTN | BR3: CTN | BS3: CTN | BT3: CTN | BU3: CTN | BV3: CTN | BW3: CTN | BX3: CTN | BY3: CTN | BZ3: CTN | CA3: CTN | CB3: CTN | CC3: CTN | CD3: CTN | CF3: CTN | CG3: CTN | CH3: CTN | CI3: CTN | CJ3: CTN | CK3: BOX
B4: 101003 | C4: JELLY ABC 48 BAGS (party pack) | D4: 1 | E4: 48 | F4: 39.437248 | H4: 31 | L4: =I4/E4 -> 0 | M4: =I4/E4 -> 0 | N4: =M4+H4 -> 31 | O4: =N4*E4 -> 1488 | P4: =O4*F4 -> 58682.625 | AW4: =SUM(R4:AV4) -> 0 | AY4: =Asghar!J4+shahzad!J4+Fahad!J4+Asif!J4+sumair!J4 -> 0 | AZ4: =Asghar!N4+shahzad!N4+Fahad!N4+Asif!N4+sumair!N4 -> 0 | BA4: =Asghar!R4+shahzad!R4+Fahad!R4+Asif!R4+sumair!R4 -> 0 | BB4: =Asghar!V4+shahzad!V4+Fahad!V4+Asif!V4+sumair!V4 -> 0 | BC4: =Asghar!Z4+shahzad!Z4+Fahad!Z4+Asif!Z4+sumair!Z4 -> 0 | BD4: =Asghar!AD4+shahzad!AD4+Fahad!AD4+Asif!AD4+sumair!AD4 -> 0 | BE4: =Asghar!AH4+shahzad!AH4+Fahad!AH4+Asif!AH4+sumair!AH4 -> 0 | BF4: =Asghar!AL4+shahzad!AL4+Fahad!AL4+Asif!AL4+sumair!AL4 -> 0 | BG4: =Asghar!AP4+shahzad!AP4+Fahad!AP4+Asif!AP4+sumair!AP4 -> 0 | BH4: =Asghar!AT4+shahzad!AT4+Fahad!AT4+Asif!AT4+sumair!AT4 -> 0 | BI4: =Asghar!AX4+shahzad!AX4+Fahad!AX4+Asif!AX4+sumair!AX4 -> 0 | BJ4: =Asghar!BB4+shahzad!BB4+Fahad!BB4+Asif!BB4+sumair!BB4 -> 0 | BK4: =Asghar!BF4+shahzad!BF4+Fahad!BF4+Asif!BF4+sumair!BF4 -> 0 | BL4: =Asghar!BJ4+shahzad!BJ4+Fahad!BJ4+Asif!BJ4+sumair!BJ4 -> 0 | BM4: =Asghar!BN4+shahzad!BN4+Fahad!BN4+Asif!BN4+sumair!BN4 -> 0 | BN4: =Asghar!BR4+shahzad!BR4+Fahad!BR4+Asif!BR4+sumair!BR4 -> 0 | BO4: =Asghar!BV4+shahzad!BV4+Fahad!BV4+Asif!BV4+sumair!BV4 -> 0 | BP4: =Asghar!BZ4+shahzad!BZ4+Fahad!BZ4+Asif!BZ4+sumair!BZ4 -> 0 | BQ4: =Asghar!CD4+shahzad!CD4+Fahad!CD4+Asif!CD4+sumair!CD4 -> 0 | BR4: =Asghar!CH4+shahzad!CH4+Fahad!CH4+Asif!CH4+sumair!CH4 -> 0 | BS4: =Asghar!CL4+shahzad!CL4+Fahad!CL4+Asif!CL4+sumair!CL4 -> 0 | BT4: =Asghar!CP4+shahzad!CP4+Fahad!CP4+Asif!CP4+sumair!CP4 -> 0 | BU4: =Asghar!CT4+shahzad!CT4+Fahad!CT4+Asif!CT4+sumair!CT4 -> 0 | BV4: =Asghar!CX4+shahzad!CX4+Fahad!CX4+Asif!CX4+sumair!CX4 -> 0 | BW4: =Asghar!DB4+shahzad!DB4+Fahad!DB4+Asif!DB4+sumair!DB4 -> 0 | BX4: =Asghar!DF4+shahzad!DF4+Fahad!DF4+Asif!DF4+sumair!DF4 -> 0 | BY4: =Asghar!DJ4+shahzad!DJ4+Fahad!DJ4+Asif!DJ4+sumair!DJ4 -> 0 | BZ4: =Asghar!DN4+shahzad!DN4+Fahad!DN4+Asif!DN4+sumair!DN4 -> 0 | CA4: =Asghar!DR4+shahzad!DR4+Fahad!DR4+Asif!DR4+sumair!DR4 -> 0 | CB4: =Asghar!DV4+shahzad!DV4+Fahad!DV4+Asif!DV4+sumair!DV4 -> 0 | CC4: =Asghar!DZ4+shahzad!DZ4+Fahad!DZ4+Asif!DZ4+sumair!DZ4 -> 0 | CD4: =SUM(AY4:CC4) -> 0 | CF4: =N4 -> 31 | CG4: =AW4 -> 0 | CH4: =CG4+CF4 -> 31 | CI4: =CD4 -> 0 | CJ4: =CH4-CI4 -> 31
B5: 101017 | C5: AMROOD JELLY 48 BAGS RS 50 (PARTY PACK) | D5: 1 | E5: 48 | F5: 39.437248 | I5: 2 | L5: =I5/E5 -> 0.041666667 | M5: =I5/E5 -> 0.041666667 | N5: =M5+H5 -> 0.041666667 | O5: =N5*E5 -> 2 | P5: =O5*F5 -> 78.874496 | AW5: =SUM(R5:AV5) -> 0 | AY5: =Asghar!J5+shahzad!J5+Fahad!J5+Asif!J5+sumair!J5 -> 0 | AZ5: =Asghar!N5+shahzad!N5+Fahad!N5+Asif!N5+sumair!N5 -> 0 | BA5: =Asghar!R5+shahzad!R5+Fahad!R5+Asif!R5+sumair!R5 -> 0 | BB5: =Asghar!V5+shahzad!V5+Fahad!V5+Asif!V5+sumair!V5 -> 0 | BC5: =Asghar!Z5+shahzad!Z5+Fahad!Z5+Asif!Z5+sumair!Z5 -> 0 | BD5: =Asghar!AD5+shahzad!AD5+Fahad!AD5+Asif!AD5+sumair!AD5 -> 0 | BE5: =Asghar!AH5+shahzad!AH5+Fahad!AH5+Asif!AH5+sumair!AH5 -> 0 | BF5: =Asghar!AL5+shahzad!AL5+Fahad!AL5+Asif!AL5+sumair!AL5 -> 0 | BG5: =Asghar!AP5+shahzad!AP5+Fahad!AP5+Asif!AP5+sumair!AP5 -> 0 | BH5: =Asghar!AT5+shahzad!AT5+Fahad!AT5+Asif!AT5+sumair!AT5 -> 0 | BI5: =Asghar!AX5+shahzad!AX5+Fahad!AX5+Asif!AX5+sumair!AX5 -> 0 | BJ5: =Asghar!BB5+shahzad!BB5+Fahad!BB5+Asif!BB5+sumair!BB5 -> 0 | BK5: =Asghar!BF5+shahzad!BF5+Fahad!BF5+Asif!BF5+sumair!BF5 -> 0 | BL5: =Asghar!BJ5+shahzad!BJ5+Fahad!BJ5+Asif!BJ5+sumair!BJ5 -> 0 | BM5: =Asghar!BN5+shahzad!BN5+Fahad!BN5+Asif!BN5+sumair!BN5 -> 0 | BN5: =Asghar!BR5+shahzad!BR5+Fahad!BR5+Asif!BR5+sumair!BR5 -> 0 | BO5: =Asghar!BV5+shahzad!BV5+Fahad!BV5+Asif!BV5+sumair!BV5 -> 0 | BP5: =Asghar!BZ5+shahzad!BZ5+Fahad!BZ5+Asif!BZ5+sumair!BZ5 -> 0 | BQ5: =Asghar!CD5+shahzad!CD5+Fahad!CD5+Asif!CD5+sumair!CD5 -> 0 | BR5: =Asghar!CH5+shahzad!CH5+Fahad!CH5+Asif!CH5+sumair!CH5 -> 0 | BS5: =Asghar!CL5+shahzad!CL5+Fahad!CL5+Asif!CL5+sumair!CL5 -> 0 | BT5: =Asghar!CP5+shahzad!CP5+Fahad!CP5+Asif!CP5+sumair!CP5 -> 0 | BU5: =Asghar!CT5+shahzad!CT5+Fahad!CT5+Asif!CT5+sumair!CT5 -> 0 | BV5: =Asghar!CX5+shahzad!CX5+Fahad!CX5+Asif!CX5+sumair!CX5 -> 0 | BW5: =Asghar!DB5+shahzad!DB5+Fahad!DB5+Asif!DB5+sumair!DB5 -> 0 | BX5: =Asghar!DF5+shahzad!DF5+Fahad!DF5+Asif!DF5+sumair!DF5 -> 0 | BY5: =Asghar!DJ5+shahzad!DJ5+Fahad!DJ5+Asif!DJ5+sumair!DJ5 -> 0 | BZ5: =Asghar!DN5+shahzad!DN5+Fahad!DN5+Asif!DN5+sumair!DN5 -> 0 | CA5: =Asghar!DR5+shahzad!DR5+Fahad!DR5+Asif!DR5+sumair!DR5 -> 0 | CB5: =Asghar!DV5+shahzad!DV5+Fahad!DV5+Asif!DV5+sumair!DV5 -> 0 | CC5: =Asghar!DZ5+shahzad!DZ5+Fahad!DZ5+Asif!DZ5+sumair!DZ5 -> 0 | CD5: =SUM(AY5:CC5) -> 0 | CF5: =N5 -> 0.041666667 | CG5: =AW5 -> 0 | CH5: =CG5+CF5 -> 0.041666667 | CI5: =CD5 -> 0 | CJ5: =CH5-CI5 -> 0.041666667
B6: 101037 | C6: BOTTLE JELLY 48 BAGS RS 50 (PARTY PACK) | D6: 1 | E6: 48 | F6: 39.437248 | H6: 10 | I6: 41 | L6: =I6/E6 -> 0.85416667 | M6: =I6/E6 -> 0.85416667 | N6: =M6+H6 -> 10.854167 | O6: =N6*E6 -> 521 | P6: =O6*F6 -> 20546.806 | AW6: =SUM(R6:AV6) -> 0 | AY6: =Asghar!J6+shahzad!J6+Fahad!J6+Asif!J6+sumair!J6 -> 0 | AZ6: =Asghar!N6+shahzad!N6+Fahad!N6+Asif!N6+sumair!N6 -> 0 | BA6: =Asghar!R6+shahzad!R6+Fahad!R6+Asif!R6+sumair!R6 -> 0 | BB6: =Asghar!V6+shahzad!V6+Fahad!V6+Asif!V6+sumair!V6 -> 0 | BC6: =Asghar!Z6+shahzad!Z6+Fahad!Z6+Asif!Z6+sumair!Z6 -> 0 | BD6: =Asghar!AD6+shahzad!AD6+Fahad!AD6+Asif!AD6+sumair!AD6 -> 0 | BE6: =Asghar!AH6+shahzad!AH6+Fahad!AH6+Asif!AH6+sumair!AH6 -> 0 | BF6: =Asghar!AL6+shahzad!AL6+Fahad!AL6+Asif!AL6+sumair!AL6 -> 0 | BG6: =Asghar!AP6+shahzad!AP6+Fahad!AP6+Asif!AP6+sumair!AP6 -> 0 | BH6: =Asghar!AT6+shahzad!AT6+Fahad!AT6+Asif!AT6+sumair!AT6 -> 0 | BI6: =Asghar!AX6+shahzad!AX6+Fahad!AX6+Asif!AX6+sumair!AX6 -> 0 | BJ6: =Asghar!BB6+shahzad!BB6+Fahad!BB6+Asif!BB6+sumair!BB6 -> 0 | BK6: =Asghar!BF6+shahzad!BF6+Fahad!BF6+Asif!BF6+sumair!BF6 -> 0 | BL6: =Asghar!BJ6+shahzad!BJ6+Fahad!BJ6+Asif!BJ6+sumair!BJ6 -> 0 | BM6: =Asghar!BN6+shahzad!BN6+Fahad!BN6+Asif!BN6+sumair!BN6 -> 0 | BN6: =Asghar!BR6+shahzad!BR6+Fahad!BR6+Asif!BR6+sumair!BR6 -> 0 | BO6: =Asghar!BV6+shahzad!BV6+Fahad!BV6+Asif!BV6+sumair!BV6 -> 0 | BP6: =Asghar!BZ6+shahzad!BZ6+Fahad!BZ6+Asif!BZ6+sumair!BZ6 -> 0 | BQ6: =Asghar!CD6+shahzad!CD6+Fahad!CD6+Asif!CD6+sumair!CD6 -> 0 | BR6: =Asghar!CH6+shahzad!CH6+Fahad!CH6+Asif!CH6+sumair!CH6 -> 0 | BS6: =Asghar!CL6+shahzad!CL6+Fahad!CL6+Asif!CL6+sumair!CL6 -> 0 | BT6: =Asghar!CP6+shahzad!CP6+Fahad!CP6+Asif!CP6+sumair!CP6 -> 0 | BU6: =Asghar!CT6+shahzad!CT6+Fahad!CT6+Asif!CT6+sumair!CT6 -> 0 | BV6: =Asghar!CX6+shahzad!CX6+Fahad!CX6+Asif!CX6+sumair!CX6 -> 0 | BW6: =Asghar!DB6+shahzad!DB6+Fahad!DB6+Asif!DB6+sumair!DB6 -> 0 | BX6: =Asghar!DF6+shahzad!DF6+Fahad!DF6+Asif!DF6+sumair!DF6 -> 0 | BY6: =Asghar!DJ6+shahzad!DJ6+Fahad!DJ6+Asif!DJ6+sumair!DJ6 -> 0 | BZ6: =Asghar!DN6+shahzad!DN6+Fahad!DN6+Asif!DN6+sumair!DN6 -> 0 | CA6: =Asghar!DR6+shahzad!DR6+Fahad!DR6+Asif!DR6+sumair!DR6 -> 0 | CB6: =Asghar!DV6+shahzad!DV6+Fahad!DV6+Asif!DV6+sumair!DV6 -> 0 | CC6: =Asghar!DZ6+shahzad!DZ6+Fahad!DZ6+Asif!DZ6+sumair!DZ6 -> 0 | CD6: =SUM(AY6:CC6) -> 0 | CF6: =N6 -> 10.854167 | CG6: =AW6 -> 0 | CH6: =CG6+CF6 -> 10.854167 | CI6: =CD6 -> 0 | CJ6: =CH6-CI6 -> 10.854167
B7: 101045 | C7: SWEET BEAR JELLY RS 20 18 BAGS X 18 BOX | D7: 18 | E7: 18 | F7: 288.68044 | L7: =I7/E7 -> 0 | M7: =I7/E7 -> 0 | N7: =M7+H7 -> 0 | O7: =N7*E7 -> 0 | P7: =O7*F7 -> 0 | AW7: =SUM(R7:AV7) -> 0 | AY7: =Asghar!J7+shahzad!J7+Fahad!J7+Asif!J7+sumair!J7 -> 0 | AZ7: =Asghar!N7+shahzad!N7+Fahad!N7+Asif!N7+sumair!N7 -> 0 | BA7: =Asghar!R7+shahzad!R7+Fahad!R7+Asif!R7+sumair!R7 -> 0 | BB7: =Asghar!V7+shahzad!V7+Fahad!V7+Asif!V7+sumair!V7 -> 0 | BC7: =Asghar!Z7+shahzad!Z7+Fahad!Z7+Asif!Z7+sumair!Z7 -> 0 | BD7: =Asghar!AD7+shahzad!AD7+Fahad!AD7+Asif!AD7+sumair!AD7 -> 0 | BE7: =Asghar!AH7+shahzad!AH7+Fahad!AH7+Asif!AH7+sumair!AH7 -> 0 | BF7: =Asghar!AL7+shahzad!AL7+Fahad!AL7+Asif!AL7+sumair!AL7 -> 0 | BG7: =Asghar!AP7+shahzad!AP7+Fahad!AP7+Asif!AP7+sumair!AP7 -> 0 | BH7: =Asghar!AT7+shahzad!AT7+Fahad!AT7+Asif!AT7+sumair!AT7 -> 0 | BI7: =Asghar!AX7+shahzad!AX7+Fahad!AX7+Asif!AX7+sumair!AX7 -> 0 | BJ7: =Asghar!BB7+shahzad!BB7+Fahad!BB7+Asif!BB7+sumair!BB7 -> 0 | BK7: =Asghar!BF7+shahzad!BF7+Fahad!BF7+Asif!BF7+sumair!BF7 -> 0 | BL7: =Asghar!BJ7+shahzad!BJ7+Fahad!BJ7+Asif!BJ7+sumair!BJ7 -> 0 | BM7: =Asghar!BN7+shahzad!BN7+Fahad!BN7+Asif!BN7+sumair!BN7 -> 0 | BN7: =Asghar!BR7+shahzad!BR7+Fahad!BR7+Asif!BR7+sumair!BR7 -> 0 | BO7: =Asghar!BV7+shahzad!BV7+Fahad!BV7+Asif!BV7+sumair!BV7 -> 0 | BP7: =Asghar!BZ7+shahzad!BZ7+Fahad!BZ7+Asif!BZ7+sumair!BZ7 -> 0 | BQ7: =Asghar!CD7+shahzad!CD7+Fahad!CD7+Asif!CD7+sumair!CD7 -> 0 | BR7: =Asghar!CH7+shahzad!CH7+Fahad!CH7+Asif!CH7+sumair!CH7 -> 0 | BS7: =Asghar!CL7+shahzad!CL7+Fahad!CL7+Asif!CL7+sumair!CL7 -> 0 | BT7: =Asghar!CP7+shahzad!CP7+Fahad!CP7+Asif!CP7+sumair!CP7 -> 0 | BU7: =Asghar!CT7+shahzad!CT7+Fahad!CT7+Asif!CT7+sumair!CT7 -> 0 | BV7: =Asghar!CX7+shahzad!CX7+Fahad!CX7+Asif!CX7+sumair!CX7 -> 0 | BW7: =Asghar!DB7+shahzad!DB7+Fahad!DB7+Asif!DB7+sumair!DB7 -> 0 | BX7: =Asghar!DF7+shahzad!DF7+Fahad!DF7+Asif!DF7+sumair!DF7 -> 0 | BY7: =Asghar!DJ7+shahzad!DJ7+Fahad!DJ7+Asif!DJ7+sumair!DJ7 -> 0 | BZ7: =Asghar!DN7+shahzad!DN7+Fahad!DN7+Asif!DN7+sumair!DN7 -> 0 | CA7: =Asghar!DR7+shahzad!DR7+Fahad!DR7+Asif!DR7+sumair!DR7 -> 0 | CB7: =Asghar!DV7+shahzad!DV7+Fahad!DV7+Asif!DV7+sumair!DV7 -> 0 | CC7: =Asghar!DZ7+shahzad!DZ7+Fahad!DZ7+Asif!DZ7+sumair!DZ7 -> 0 | CD7: =SUM(AY7:CC7) -> 0 | CF7: =N7 -> 0 | CG7: =AW7 -> 0 | CH7: =CG7+CF7 -> 0 | CI7: =CD7 -> 0 | CJ7: =CH7-CI7 -> 0
B8: 101057 | C8: FIZZY O JELLY 48 BAGS RS 50 (PARTY PACK) | D8: 1 | E8: 48 | F8: 39.437248 | H8: 4 | I8: 23 | L8: =I8/E8 -> 0.47916667 | M8: =I8/E8 -> 0.47916667 | N8: =M8+H8 -> 4.4791667 | O8: =N8*E8 -> 215 | P8: =O8*F8 -> 8479.0083 | AW8: =SUM(R8:AV8) -> 0 | AY8: =Asghar!J8+shahzad!J8+Fahad!J8+Asif!J8+sumair!J8 -> 0 | AZ8: =Asghar!N8+shahzad!N8+Fahad!N8+Asif!N8+sumair!N8 -> 0 | BA8: =Asghar!R8+shahzad!R8+Fahad!R8+Asif!R8+sumair!R8 -> 0 | BB8: =Asghar!V8+shahzad!V8+Fahad!V8+Asif!V8+sumair!V8 -> 0 | BC8: =Asghar!Z8+shahzad!Z8+Fahad!Z8+Asif!Z8+sumair!Z8 -> 0 | BD8: =Asghar!AD8+shahzad!AD8+Fahad!AD8+Asif!AD8+sumair!AD8 -> 0 | BE8: =Asghar!AH8+shahzad!AH8+Fahad!AH8+Asif!AH8+sumair!AH8 -> 0 | BF8: =Asghar!AL8+shahzad!AL8+Fahad!AL8+Asif!AL8+sumair!AL8 -> 0 | BG8: =Asghar!AP8+shahzad!AP8+Fahad!AP8+Asif!AP8+sumair!AP8 -> 0 | BH8: =Asghar!AT8+shahzad!AT8+Fahad!AT8+Asif!AT8+sumair!AT8 -> 0 | BI8: =Asghar!AX8+shahzad!AX8+Fahad!AX8+Asif!AX8+sumair!AX8 -> 0 | BJ8: =Asghar!BB8+shahzad!BB8+Fahad!BB8+Asif!BB8+sumair!BB8 -> 0 | BK8: =Asghar!BF8+shahzad!BF8+Fahad!BF8+Asif!BF8+sumair!BF8 -> 0 | BL8: =Asghar!BJ8+shahzad!BJ8+Fahad!BJ8+Asif!BJ8+sumair!BJ8 -> 0 | BM8: =Asghar!BN8+shahzad!BN8+Fahad!BN8+Asif!BN8+sumair!BN8 -> 0 | BN8: =Asghar!BR8+shahzad!BR8+Fahad!BR8+Asif!BR8+sumair!BR8 -> 0 | BO8: =Asghar!BV8+shahzad!BV8+Fahad!BV8+Asif!BV8+sumair!BV8 -> 0 | BP8: =Asghar!BZ8+shahzad!BZ8+Fahad!BZ8+Asif!BZ8+sumair!BZ8 -> 0 | BQ8: =Asghar!CD8+shahzad!CD8+Fahad!CD8+Asif!CD8+sumair!CD8 -> 0 | BR8: =Asghar!CH8+shahzad!CH8+Fahad!CH8+Asif!CH8+sumair!CH8 -> 0 | BS8: =Asghar!CL8+shahzad!CL8+Fahad!CL8+Asif!CL8+sumair!CL8 -> 0 | BT8: =Asghar!CP8+shahzad!CP8+Fahad!CP8+Asif!CP8+sumair!CP8 -> 0 | BU8: =Asghar!CT8+shahzad!CT8+Fahad!CT8+Asif!CT8+sumair!CT8 -> 0 | BV8: =Asghar!CX8+shahzad!CX8+Fahad!CX8+Asif!CX8+sumair!CX8 -> 0 | BW8: =Asghar!DB8+shahzad!DB8+Fahad!DB8+Asif!DB8+sumair!DB8 -> 0 | BX8: =Asghar!DF8+shahzad!DF8+Fahad!DF8+Asif!DF8+sumair!DF8 -> 0 | BY8: =Asghar!DJ8+shahzad!DJ8+Fahad!DJ8+Asif!DJ8+sumair!DJ8 -> 0 | BZ8: =Asghar!DN8+shahzad!DN8+Fahad!DN8+Asif!DN8+sumair!DN8 -> 0 | CA8: =Asghar!DR8+shahzad!DR8+Fahad!DR8+Asif!DR8+sumair!DR8 -> 0 | CB8: =Asghar!DV8+shahzad!DV8+Fahad!DV8+Asif!DV8+sumair!DV8 -> 0 | CC8: =Asghar!DZ8+shahzad!DZ8+Fahad!DZ8+Asif!DZ8+sumair!DZ8 -> 0 | CD8: =SUM(AY8:CC8) -> 0 | CF8: =N8 -> 4.4791667 | CG8: =AW8 -> 0 | CH8: =CG8+CF8 -> 4.4791667 | CI8: =CD8 -> 0 | CJ8: =CH8-CI8 -> 4.4791667
B9: 101058 | C9: FIZZY O JELLY RS 10 24 BAGS X 24 BOXES | D9: 24 | E9: 24 | F9: 189.29879 | H9: 5 | I9: 13 | L9: =I9/E9 -> 0.54166667 | M9: =I9/E9 -> 0.54166667 | N9: =M9+H9 -> 5.5416667 | O9: =N9*E9 -> 133 | P9: =O9*F9 -> 25176.739 | AW9: =SUM(R9:AV9) -> 0 | AY9: =Asghar!J9+shahzad!J9+Fahad!J9+Asif!J9+sumair!J9 -> 0 | AZ9: =Asghar!N9+shahzad!N9+Fahad!N9+Asif!N9+sumair!N9 -> 0 | BA9: =Asghar!R9+shahzad!R9+Fahad!R9+Asif!R9+sumair!R9 -> 0 | BB9: =Asghar!V9+shahzad!V9+Fahad!V9+Asif!V9+sumair!V9 -> 0 | BC9: =Asghar!Z9+shahzad!Z9+Fahad!Z9+Asif!Z9+sumair!Z9 -> 0 | BD9: =Asghar!AD9+shahzad!AD9+Fahad!AD9+Asif!AD9+sumair!AD9 -> 0 | BE9: =Asghar!AH9+shahzad!AH9+Fahad!AH9+Asif!AH9+sumair!AH9 -> 0 | BF9: =Asghar!AL9+shahzad!AL9+Fahad!AL9+Asif!AL9+sumair!AL9 -> 0 | BG9: =Asghar!AP9+shahzad!AP9+Fahad!AP9+Asif!AP9+sumair!AP9 -> 0 | BH9: =Asghar!AT9+shahzad!AT9+Fahad!AT9+Asif!AT9+sumair!AT9 -> 0 | BI9: =Asghar!AX9+shahzad!AX9+Fahad!AX9+Asif!AX9+sumair!AX9 -> 0 | BJ9: =Asghar!BB9+shahzad!BB9+Fahad!BB9+Asif!BB9+sumair!BB9 -> 0 | BK9: =Asghar!BF9+shahzad!BF9+Fahad!BF9+Asif!BF9+sumair!BF9 -> 0 | BL9: =Asghar!BJ9+shahzad!BJ9+Fahad!BJ9+Asif!BJ9+sumair!BJ9 -> 0 | BM9: =Asghar!BN9+shahzad!BN9+Fahad!BN9+Asif!BN9+sumair!BN9 -> 0 | BN9: =Asghar!BR9+shahzad!BR9+Fahad!BR9+Asif!BR9+sumair!BR9 -> 0 | BO9: =Asghar!BV9+shahzad!BV9+Fahad!BV9+Asif!BV9+sumair!BV9 -> 0 | BP9: =Asghar!BZ9+shahzad!BZ9+Fahad!BZ9+Asif!BZ9+sumair!BZ9 -> 0 | BQ9: =Asghar!CD9+shahzad!CD9+Fahad!CD9+Asif!CD9+sumair!CD9 -> 0 | BR9: =Asghar!CH9+shahzad!CH9+Fahad!CH9+Asif!CH9+sumair!CH9 -> 0 | BS9: =Asghar!CL9+shahzad!CL9+Fahad!CL9+Asif!CL9+sumair!CL9 -> 0 | BT9: =Asghar!CP9+shahzad!CP9+Fahad!CP9+Asif!CP9+sumair!CP9 -> 0 | BU9: =Asghar!CT9+shahzad!CT9+Fahad!CT9+Asif!CT9+sumair!CT9 -> 0 | BV9: =Asghar!CX9+shahzad!CX9+Fahad!CX9+Asif!CX9+sumair!CX9 -> 0 | BW9: =Asghar!DB9+shahzad!DB9+Fahad!DB9+Asif!DB9+sumair!DB9 -> 0 | BX9: =Asghar!DF9+shahzad!DF9+Fahad!DF9+Asif!DF9+sumair!DF9 -> 0 | BY9: =Asghar!DJ9+shahzad!DJ9+Fahad!DJ9+Asif!DJ9+sumair!DJ9 -> 0 | BZ9: =Asghar!DN9+shahzad!DN9+Fahad!DN9+Asif!DN9+sumair!DN9 -> 0 | CA9: =Asghar!DR9+shahzad!DR9+Fahad!DR9+Asif!DR9+sumair!DR9 -> 0 | CB9: =Asghar!DV9+shahzad!DV9+Fahad!DV9+Asif!DV9+sumair!DV9 -> 0 | CC9: =Asghar!DZ9+shahzad!DZ9+Fahad!DZ9+Asif!DZ9+sumair!DZ9 -> 0 | CD9: =SUM(AY9:CC9) -> 0 | CF9: =N9 -> 5.5416667 | CG9: =AW9 -> 0 | CH9: =CG9+CF9 -> 5.5416667 | CI9: =CD9 -> 0 | CJ9: =CH9-CI9 -> 5.5416667
B10: 101205 | C10: JELLY CHILLI MILLI 48 BAGS (PARTY PACK) | D10: 1 | E10: 48 | F10: 39.437248 | H10: 27 | I10: 16 | L10: =I10/E10 -> 0.33333333 | M10: =I10/E10 -> 0.33333333 | N10: =M10+H10 -> 27.333333 | O10: =N10*E10 -> 1312 | P10: =O10*F10 -> 51741.67 | AW10: =SUM(R10:AV10) -> 0 | AY10: =Asghar!J10+shahzad!J10+Fahad!J10+Asif!J10+sumair!J10 -> 0 | AZ10: =Asghar!N10+shahzad!N10+Fahad!N10+Asif!N10+sumair!N10 -> 0 | BA10: =Asghar!R10+shahzad!R10+Fahad!R10+Asif!R10+sumair!R10 -> 0 | BB10: =Asghar!V10+shahzad!V10+Fahad!V10+Asif!V10+sumair!V10 -> 0 | BC10: =Asghar!Z10+shahzad!Z10+Fahad!Z10+Asif!Z10+sumair!Z10 -> 0 | BD10: =Asghar!AD10+shahzad!AD10+Fahad!AD10+Asif!AD10+sumair!AD10 -> 0 | BE10: =Asghar!AH10+shahzad!AH10+Fahad!AH10+Asif!AH10+sumair!AH10 -> 0 | BF10: =Asghar!AL10+shahzad!AL10+Fahad!AL10+Asif!AL10+sumair!AL10 -> 0 | BG10: =Asghar!AP10+shahzad!AP10+Fahad!AP10+Asif!AP10+sumair!AP10 -> 0 | BH10: =Asghar!AT10+shahzad!AT10+Fahad!AT10+Asif!AT10+sumair!AT10 -> 0 | BI10: =Asghar!AX10+shahzad!AX10+Fahad!AX10+Asif!AX10+sumair!AX10 -> 0 | BJ10: =Asghar!BB10+shahzad!BB10+Fahad!BB10+Asif!BB10+sumair!BB10 -> 0 | BK10: =Asghar!BF10+shahzad!BF10+Fahad!BF10+Asif!BF10+sumair!BF10 -> 0 | BL10: =Asghar!BJ10+shahzad!BJ10+Fahad!BJ10+Asif!BJ10+sumair!BJ10 -> 0 | BM10: =Asghar!BN10+shahzad!BN10+Fahad!BN10+Asif!BN10+sumair!BN10 -> 0 | BN10: =Asghar!BR10+shahzad!BR10+Fahad!BR10+Asif!BR10+sumair!BR10 -> 0 | BO10: =Asghar!BV10+shahzad!BV10+Fahad!BV10+Asif!BV10+sumair!BV10 -> 0 | BP10: =Asghar!BZ10+shahzad!BZ10+Fahad!BZ10+Asif!BZ10+sumair!BZ10 -> 0 | BQ10: =Asghar!CD10+shahzad!CD10+Fahad!CD10+Asif!CD10+sumair!CD10 -> 0 | BR10: =Asghar!CH10+shahzad!CH10+Fahad!CH10+Asif!CH10+sumair!CH10 -> 0 | BS10: =Asghar!CL10+shahzad!CL10+Fahad!CL10+Asif!CL10+sumair!CL10 -> 0 | BT10: =Asghar!CP10+shahzad!CP10+Fahad!CP10+Asif!CP10+sumair!CP10 -> 0 | BU10: =Asghar!CT10+shahzad!CT10+Fahad!CT10+Asif!CT10+sumair!CT10 -> 0 | BV10: =Asghar!CX10+shahzad!CX10+Fahad!CX10+Asif!CX10+sumair!CX10 -> 0 | BW10: =Asghar!DB10+shahzad!DB10+Fahad!DB10+Asif!DB10+sumair!DB10 -> 0 | BX10: =Asghar!DF10+shahzad!DF10+Fahad!DF10+Asif!DF10+sumair!DF10 -> 0 | BY10: =Asghar!DJ10+shahzad!DJ10+Fahad!DJ10+Asif!DJ10+sumair!DJ10 -> 0 | BZ10: =Asghar!DN10+shahzad!DN10+Fahad!DN10+Asif!DN10+sumair!DN10 -> 0 | CA10: =Asghar!DR10+shahzad!DR10+Fahad!DR10+Asif!DR10+sumair!DR10 -> 0 | CB10: =Asghar!DV10+shahzad!DV10+Fahad!DV10+Asif!DV10+sumair!DV10 -> 0 | CC10: =Asghar!DZ10+shahzad!DZ10+Fahad!DZ10+Asif!DZ10+sumair!DZ10 -> 0 | CD10: =SUM(AY10:CC10) -> 0 | CF10: =N10 -> 27.333333 | CG10: =AW10 -> 0 | CH10: =CG10+CF10 -> 27.333333 | CI10: =CD10 -> 0 | CJ10: =CH10-CI10 -> 27.333333
B11: 101333 | C11: CHILLI MILLI RS10 24 BAGS X 24 BOXES | D11: 24 | E11: 24 | F11: 189.29879 | H11: 60 | I11: 19 | L11: =I11/E11 -> 0.79166667 | M11: =I11/E11 -> 0.79166667 | N11: =M11+H11 -> 60.791667 | O11: =N11*E11 -> 1459 | P11: =O11*F11 -> 276186.94 | AW11: =SUM(R11:AV11) -> 0 | AY11: =Asghar!J11+shahzad!J11+Fahad!J11+Asif!J11+sumair!J11 -> 0 | AZ11: =Asghar!N11+shahzad!N11+Fahad!N11+Asif!N11+sumair!N11 -> 0 | BA11: =Asghar!R11+shahzad!R11+Fahad!R11+Asif!R11+sumair!R11 -> 0 | BB11: =Asghar!V11+shahzad!V11+Fahad!V11+Asif!V11+sumair!V11 -> 0 | BC11: =Asghar!Z11+shahzad!Z11+Fahad!Z11+Asif!Z11+sumair!Z11 -> 0 | BD11: =Asghar!AD11+shahzad!AD11+Fahad!AD11+Asif!AD11+sumair!AD11 -> 0 | BE11: =Asghar!AH11+shahzad!AH11+Fahad!AH11+Asif!AH11+sumair!AH11 -> 0 | BF11: =Asghar!AL11+shahzad!AL11+Fahad!AL11+Asif!AL11+sumair!AL11 -> 0 | BG11: =Asghar!AP11+shahzad!AP11+Fahad!AP11+Asif!AP11+sumair!AP11 -> 0 | BH11: =Asghar!AT11+shahzad!AT11+Fahad!AT11+Asif!AT11+sumair!AT11 -> 0 | BI11: =Asghar!AX11+shahzad!AX11+Fahad!AX11+Asif!AX11+sumair!AX11 -> 0 | BJ11: =Asghar!BB11+shahzad!BB11+Fahad!BB11+Asif!BB11+sumair!BB11 -> 0 | BK11: =Asghar!BF11+shahzad!BF11+Fahad!BF11+Asif!BF11+sumair!BF11 -> 0 | BL11: =Asghar!BJ11+shahzad!BJ11+Fahad!BJ11+Asif!BJ11+sumair!BJ11 -> 0 | BM11: =Asghar!BN11+shahzad!BN11+Fahad!BN11+Asif!BN11+sumair!BN11 -> 0 | BN11: =Asghar!BR11+shahzad!BR11+Fahad!BR11+Asif!BR11+sumair!BR11 -> 0 | BO11: =Asghar!BV11+shahzad!BV11+Fahad!BV11+Asif!BV11+sumair!BV11 -> 0 | BP11: =Asghar!BZ11+shahzad!BZ11+Fahad!BZ11+Asif!BZ11+sumair!BZ11 -> 0 | BQ11: =Asghar!CD11+shahzad!CD11+Fahad!CD11+Asif!CD11+sumair!CD11 -> 0 | BR11: =Asghar!CH11+shahzad!CH11+Fahad!CH11+Asif!CH11+sumair!CH11 -> 0 | BS11: =Asghar!CL11+shahzad!CL11+Fahad!CL11+Asif!CL11+sumair!CL11 -> 0 | BT11: =Asghar!CP11+shahzad!CP11+Fahad!CP11+Asif!CP11+sumair!CP11 -> 0 | BU11: =Asghar!CT11+shahzad!CT11+Fahad!CT11+Asif!CT11+sumair!CT11 -> 0 | BV11: =Asghar!CX11+shahzad!CX11+Fahad!CX11+Asif!CX11+sumair!CX11 -> 0 | BW11: =Asghar!DB11+shahzad!DB11+Fahad!DB11+Asif!DB11+sumair!DB11 -> 0 | BX11: =Asghar!DF11+shahzad!DF11+Fahad!DF11+Asif!DF11+sumair!DF11 -> 0 | BY11: =Asghar!DJ11+shahzad!DJ11+Fahad!DJ11+Asif!DJ11+sumair!DJ11 -> 0 | BZ11: =Asghar!DN11+shahzad!DN11+Fahad!DN11+Asif!DN11+sumair!DN11 -> 0 | CA11: =Asghar!DR11+shahzad!DR11+Fahad!DR11+Asif!DR11+sumair!DR11 -> 0 | CB11: =Asghar!DV11+shahzad!DV11+Fahad!DV11+Asif!DV11+sumair!DV11 -> 0 | CC11: =Asghar!DZ11+shahzad!DZ11+Fahad!DZ11+Asif!DZ11+sumair!DZ11 -> 0 | CD11: =SUM(AY11:CC11) -> 0 | CF11: =N11 -> 60.791667 | CG11: =AW11 -> 0 | CH11: =CG11+CF11 -> 60.791667 | CI11: =CD11 -> 0 | CJ11: =CH11-CI11 -> 60.791667
B12: 101354 | C12: ABC JELLY RS10 24 BAGS X 24 BOXES | D12: 24 | E12: 24 | F12: 189.29879 | H12: 42 | I12: 10 | L12: =I12/E12 -> 0.41666667 | M12: =I12/E12 -> 0.41666667 | N12: =M12+H12 -> 42.416667 | O12: =N12*E12 -> 1018 | P12: =O12*F12 -> 192706.17 | AW12: =SUM(R12:AV12) -> 0 | AY12: =Asghar!J12+shahzad!J12+Fahad!J12+Asif!J12+sumair!J12 -> 0 | AZ12: =Asghar!N12+shahzad!N12+Fahad!N12+Asif!N12+sumair!N12 -> 0 | BA12: =Asghar!R12+shahzad!R12+Fahad!R12+Asif!R12+sumair!R12 -> 0 | BB12: =Asghar!V12+shahzad!V12+Fahad!V12+Asif!V12+sumair!V12 -> 0 | BC12: =Asghar!Z12+shahzad!Z12+Fahad!Z12+Asif!Z12+sumair!Z12 -> 0 | BD12: =Asghar!AD12+shahzad!AD12+Fahad!AD12+Asif!AD12+sumair!AD12 -> 0 | BE12: =Asghar!AH12+shahzad!AH12+Fahad!AH12+Asif!AH12+sumair!AH12 -> 0 | BF12: =Asghar!AL12+shahzad!AL12+Fahad!AL12+Asif!AL12+sumair!AL12 -> 0 | BG12: =Asghar!AP12+shahzad!AP12+Fahad!AP12+Asif!AP12+sumair!AP12 -> 0 | BH12: =Asghar!AT12+shahzad!AT12+Fahad!AT12+Asif!AT12+sumair!AT12 -> 0 | BI12: =Asghar!AX12+shahzad!AX12+Fahad!AX12+Asif!AX12+sumair!AX12 -> 0 | BJ12: =Asghar!BB12+shahzad!BB12+Fahad!BB12+Asif!BB12+sumair!BB12 -> 0 | BK12: =Asghar!BF12+shahzad!BF12+Fahad!BF12+Asif!BF12+sumair!BF12 -> 0 | BL12: =Asghar!BJ12+shahzad!BJ12+Fahad!BJ12+Asif!BJ12+sumair!BJ12 -> 0 | BM12: =Asghar!BN12+shahzad!BN12+Fahad!BN12+Asif!BN12+sumair!BN12 -> 0 | BN12: =Asghar!BR12+shahzad!BR12+Fahad!BR12+Asif!BR12+sumair!BR12 -> 0 | BO12: =Asghar!BV12+shahzad!BV12+Fahad!BV12+Asif!BV12+sumair!BV12 -> 0 | BP12: =Asghar!BZ12+shahzad!BZ12+Fahad!BZ12+Asif!BZ12+sumair!BZ12 -> 0 | BQ12: =Asghar!CD12+shahzad!CD12+Fahad!CD12+Asif!CD12+sumair!CD12 -> 0 | BR12: =Asghar!CH12+shahzad!CH12+Fahad!CH12+Asif!CH12+sumair!CH12 -> 0 | BS12: =Asghar!CL12+shahzad!CL12+Fahad!CL12+Asif!CL12+sumair!CL12 -> 0 | BT12: =Asghar!CP12+shahzad!CP12+Fahad!CP12+Asif!CP12+sumair!CP12 -> 0 | BU12: =Asghar!CT12+shahzad!CT12+Fahad!CT12+Asif!CT12+sumair!CT12 -> 0 | BV12: =Asghar!CX12+shahzad!CX12+Fahad!CX12+Asif!CX12+sumair!CX12 -> 0 | BW12: =Asghar!DB12+shahzad!DB12+Fahad!DB12+Asif!DB12+sumair!DB12 -> 0 | BX12: =Asghar!DF12+shahzad!DF12+Fahad!DF12+Asif!DF12+sumair!DF12 -> 0 | BY12: =Asghar!DJ12+shahzad!DJ12+Fahad!DJ12+Asif!DJ12+sumair!DJ12 -> 0 | BZ12: =Asghar!DN12+shahzad!DN12+Fahad!DN12+Asif!DN12+sumair!DN12 -> 0 | CA12: =Asghar!DR12+shahzad!DR12+Fahad!DR12+Asif!DR12+sumair!DR12 -> 0 | CB12: =Asghar!DV12+shahzad!DV12+Fahad!DV12+Asif!DV12+sumair!DV12 -> 0 | CC12: =Asghar!DZ12+shahzad!DZ12+Fahad!DZ12+Asif!DZ12+sumair!DZ12 -> 0 | CD12: =SUM(AY12:CC12) -> 0 | CF12: =N12 -> 42.416667 | CG12: =AW12 -> 0 | CH12: =CG12+CF12 -> 42.416667 | CI12: =CD12 -> 0 | CJ12: =CH12-CI12 -> 42.416667
B13: 101835 | C13: SOUR BITES JELLY RS10 24 BAGS X 24 BOXES | D13: 24 | E13: 24 | F13: 192.45358 | H13: 18 | L13: =I13/E13 -> 0 | M13: =I13/E13 -> 0 | N13: =M13+H13 -> 18 | O13: =N13*E13 -> 432 | P13: =O13*F13 -> 83139.944 | AW13: =SUM(R13:AV13) -> 0 | AY13: =Asghar!J13+shahzad!J13+Fahad!J13+Asif!J13+sumair!J13 -> 0 | AZ13: =Asghar!N13+shahzad!N13+Fahad!N13+Asif!N13+sumair!N13 -> 0 | BA13: =Asghar!R13+shahzad!R13+Fahad!R13+Asif!R13+sumair!R13 -> 0 | BB13: =Asghar!V13+shahzad!V13+Fahad!V13+Asif!V13+sumair!V13 -> 0 | BC13: =Asghar!Z13+shahzad!Z13+Fahad!Z13+Asif!Z13+sumair!Z13 -> 0 | BD13: =Asghar!AD13+shahzad!AD13+Fahad!AD13+Asif!AD13+sumair!AD13 -> 0 | BE13: =Asghar!AH13+shahzad!AH13+Fahad!AH13+Asif!AH13+sumair!AH13 -> 0 | BF13: =Asghar!AL13+shahzad!AL13+Fahad!AL13+Asif!AL13+sumair!AL13 -> 0 | BG13: =Asghar!AP13+shahzad!AP13+Fahad!AP13+Asif!AP13+sumair!AP13 -> 0 | BH13: =Asghar!AT13+shahzad!AT13+Fahad!AT13+Asif!AT13+sumair!AT13 -> 0 | BI13: =Asghar!AX13+shahzad!AX13+Fahad!AX13+Asif!AX13+sumair!AX13 -> 0 | BJ13: =Asghar!BB13+shahzad!BB13+Fahad!BB13+Asif!BB13+sumair!BB13 -> 0 | BK13: =Asghar!BF13+shahzad!BF13+Fahad!BF13+Asif!BF13+sumair!BF13 -> 0 | BL13: =Asghar!BJ13+shahzad!BJ13+Fahad!BJ13+Asif!BJ13+sumair!BJ13 -> 0 | BM13: =Asghar!BN13+shahzad!BN13+Fahad!BN13+Asif!BN13+sumair!BN13 -> 0 | BN13: =Asghar!BR13+shahzad!BR13+Fahad!BR13+Asif!BR13+sumair!BR13 -> 0 | BO13: =Asghar!BV13+shahzad!BV13+Fahad!BV13+Asif!BV13+sumair!BV13 -> 0 | BP13: =Asghar!BZ13+shahzad!BZ13+Fahad!BZ13+Asif!BZ13+sumair!BZ13 -> 0 | BQ13: =Asghar!CD13+shahzad!CD13+Fahad!CD13+Asif!CD13+sumair!CD13 -> 0 | BR13: =Asghar!CH13+shahzad!CH13+Fahad!CH13+Asif!CH13+sumair!CH13 -> 0 | BS13: =Asghar!CL13+shahzad!CL13+Fahad!CL13+Asif!CL13+sumair!CL13 -> 0 | BT13: =Asghar!CP13+shahzad!CP13+Fahad!CP13+Asif!CP13+sumair!CP13 -> 0 | BU13: =Asghar!CT13+shahzad!CT13+Fahad!CT13+Asif!CT13+sumair!CT13 -> 0 | BV13: =Asghar!CX13+shahzad!CX13+Fahad!CX13+Asif!CX13+sumair!CX13 -> 0 | BW13: =Asghar!DB13+shahzad!DB13+Fahad!DB13+Asif!DB13+sumair!DB13 -> 0 | BX13: =Asghar!DF13+shahzad!DF13+Fahad!DF13+Asif!DF13+sumair!DF13 -> 0 | BY13: =Asghar!DJ13+shahzad!DJ13+Fahad!DJ13+Asif!DJ13+sumair!DJ13 -> 0 | BZ13: =Asghar!DN13+shahzad!DN13+Fahad!DN13+Asif!DN13+sumair!DN13 -> 0 | CA13: =Asghar!DR13+shahzad!DR13+Fahad!DR13+Asif!DR13+sumair!DR13 -> 0 | CB13: =Asghar!DV13+shahzad!DV13+Fahad!DV13+Asif!DV13+sumair!DV13 -> 0 | CC13: =Asghar!DZ13+shahzad!DZ13+Fahad!DZ13+Asif!DZ13+sumair!DZ13 -> 0 | CD13: =SUM(AY13:CC13) -> 0 | CF13: =N13 -> 18 | CG13: =AW13 -> 0 | CH13: =CG13+CF13 -> 18 | CI13: =CD13 -> 0 | CJ13: =CH13-CI13 -> 18
B14: 101861 | C14: SWEET BURGER JELLY RS 10 24 PC X 12 BOX | D14: 24 | E14: 12 | F14: 187.19547 | H14: 11 | I14: 9 | L14: =I14/E14 -> 0.75 | M14: =I14/E14 -> 0.75 | N14: =M14+H14 -> 11.75 | O14: =N14*E14 -> 141 | P14: =O14*F14 -> 26394.561 | AW14: =SUM(R14:AV14) -> 0 | AY14: =Asghar!J14+shahzad!J14+Fahad!J14+Asif!J14+sumair!J14 -> 0 | AZ14: =Asghar!N14+shahzad!N14+Fahad!N14+Asif!N14+sumair!N14 -> 0 | BA14: =Asghar!R14+shahzad!R14+Fahad!R14+Asif!R14+sumair!R14 -> 0 | BB14: =Asghar!V14+shahzad!V14+Fahad!V14+Asif!V14+sumair!V14 -> 0 | BC14: =Asghar!Z14+shahzad!Z14+Fahad!Z14+Asif!Z14+sumair!Z14 -> 0 | BD14: =Asghar!AD14+shahzad!AD14+Fahad!AD14+Asif!AD14+sumair!AD14 -> 0 | BE14: =Asghar!AH14+shahzad!AH14+Fahad!AH14+Asif!AH14+sumair!AH14 -> 0 | BF14: =Asghar!AL14+shahzad!AL14+Fahad!AL14+Asif!AL14+sumair!AL14 -> 0 | BG14: =Asghar!AP14+shahzad!AP14+Fahad!AP14+Asif!AP14+sumair!AP14 -> 0 | BH14: =Asghar!AT14+shahzad!AT14+Fahad!AT14+Asif!AT14+sumair!AT14 -> 0 | BI14: =Asghar!AX14+shahzad!AX14+Fahad!AX14+Asif!AX14+sumair!AX14 -> 0 | BJ14: =Asghar!BB14+shahzad!BB14+Fahad!BB14+Asif!BB14+sumair!BB14 -> 0 | BK14: =Asghar!BF14+shahzad!BF14+Fahad!BF14+Asif!BF14+sumair!BF14 -> 0 | BL14: =Asghar!BJ14+shahzad!BJ14+Fahad!BJ14+Asif!BJ14+sumair!BJ14 -> 0 | BM14: =Asghar!BN14+shahzad!BN14+Fahad!BN14+Asif!BN14+sumair!BN14 -> 0 | BN14: =Asghar!BR14+shahzad!BR14+Fahad!BR14+Asif!BR14+sumair!BR14 -> 0 | BO14: =Asghar!BV14+shahzad!BV14+Fahad!BV14+Asif!BV14+sumair!BV14 -> 0 | BP14: =Asghar!BZ14+shahzad!BZ14+Fahad!BZ14+Asif!BZ14+sumair!BZ14 -> 0 | BQ14: =Asghar!CD14+shahzad!CD14+Fahad!CD14+Asif!CD14+sumair!CD14 -> 0 | BR14: =Asghar!CH14+shahzad!CH14+Fahad!CH14+Asif!CH14+sumair!CH14 -> 0 | BS14: =Asghar!CL14+shahzad!CL14+Fahad!CL14+Asif!CL14+sumair!CL14 -> 0 | BT14: =Asghar!CP14+shahzad!CP14+Fahad!CP14+Asif!CP14+sumair!CP14 -> 0 | BU14: =Asghar!CT14+shahzad!CT14+Fahad!CT14+Asif!CT14+sumair!CT14 -> 0 | BV14: =Asghar!CX14+shahzad!CX14+Fahad!CX14+Asif!CX14+sumair!CX14 -> 0 | BW14: =Asghar!DB14+shahzad!DB14+Fahad!DB14+Asif!DB14+sumair!DB14 -> 0 | BX14: =Asghar!DF14+shahzad!DF14+Fahad!DF14+Asif!DF14+sumair!DF14 -> 0 | BY14: =Asghar!DJ14+shahzad!DJ14+Fahad!DJ14+Asif!DJ14+sumair!DJ14 -> 0 | BZ14: =Asghar!DN14+shahzad!DN14+Fahad!DN14+Asif!DN14+sumair!DN14 -> 0 | CA14: =Asghar!DR14+shahzad!DR14+Fahad!DR14+Asif!DR14+sumair!DR14 -> 0 | CB14: =Asghar!DV14+shahzad!DV14+Fahad!DV14+Asif!DV14+sumair!DV14 -> 0 | CC14: =Asghar!DZ14+shahzad!DZ14+Fahad!DZ14+Asif!DZ14+sumair!DZ14 -> 0 | CD14: =SUM(AY14:CC14) -> 0 | CF14: =N14 -> 11.75 | CG14: =AW14 -> 0 | CH14: =CG14+CF14 -> 11.75 | CI14: =CD14 -> 0 | CJ14: =CH14-CI14 -> 11.75
B15: 101879 | C15: DINO JELLY RS 20 18 BAGS X 18 BOX | D15: 18 | E15: 18 | F15: 288.68044 | H15: 7 | I15: 10 | L15: =I15/E15 -> 0.55555556 | M15: =I15/E15 -> 0.55555556 | N15: =M15+H15 -> 7.5555556 | O15: =N15*E15 -> 136 | P15: =O15*F15 -> 39260.54 | AW15: =SUM(R15:AV15) -> 0 | AY15: =Asghar!J15+shahzad!J15+Fahad!J15+Asif!J15+sumair!J15 -> 0 | AZ15: =Asghar!N15+shahzad!N15+Fahad!N15+Asif!N15+sumair!N15 -> 0 | BA15: =Asghar!R15+shahzad!R15+Fahad!R15+Asif!R15+sumair!R15 -> 0 | BB15: =Asghar!V15+shahzad!V15+Fahad!V15+Asif!V15+sumair!V15 -> 0 | BC15: =Asghar!Z15+shahzad!Z15+Fahad!Z15+Asif!Z15+sumair!Z15 -> 0 | BD15: =Asghar!AD15+shahzad!AD15+Fahad!AD15+Asif!AD15+sumair!AD15 -> 0 | BE15: =Asghar!AH15+shahzad!AH15+Fahad!AH15+Asif!AH15+sumair!AH15 -> 0 | BF15: =Asghar!AL15+shahzad!AL15+Fahad!AL15+Asif!AL15+sumair!AL15 -> 0 | BG15: =Asghar!AP15+shahzad!AP15+Fahad!AP15+Asif!AP15+sumair!AP15 -> 0 | BH15: =Asghar!AT15+shahzad!AT15+Fahad!AT15+Asif!AT15+sumair!AT15 -> 0 | BI15: =Asghar!AX15+shahzad!AX15+Fahad!AX15+Asif!AX15+sumair!AX15 -> 0 | BJ15: =Asghar!BB15+shahzad!BB15+Fahad!BB15+Asif!BB15+sumair!BB15 -> 0 | BK15: =Asghar!BF15+shahzad!BF15+Fahad!BF15+Asif!BF15+sumair!BF15 -> 0 | BL15: =Asghar!BJ15+shahzad!BJ15+Fahad!BJ15+Asif!BJ15+sumair!BJ15 -> 0 | BM15: =Asghar!BN15+shahzad!BN15+Fahad!BN15+Asif!BN15+sumair!BN15 -> 0 | BN15: =Asghar!BR15+shahzad!BR15+Fahad!BR15+Asif!BR15+sumair!BR15 -> 0 | BO15: =Asghar!BV15+shahzad!BV15+Fahad!BV15+Asif!BV15+sumair!BV15 -> 0 | BP15: =Asghar!BZ15+shahzad!BZ15+Fahad!BZ15+Asif!BZ15+sumair!BZ15 -> 0 | BQ15: =Asghar!CD15+shahzad!CD15+Fahad!CD15+Asif!CD15+sumair!CD15 -> 0 | BR15: =Asghar!CH15+shahzad!CH15+Fahad!CH15+Asif!CH15+sumair!CH15 -> 0 | BS15: =Asghar!CL15+shahzad!CL15+Fahad!CL15+Asif!CL15+sumair!CL15 -> 0 | BT15: =Asghar!CP15+shahzad!CP15+Fahad!CP15+Asif!CP15+sumair!CP15 -> 0 | BU15: =Asghar!CT15+shahzad!CT15+Fahad!CT15+Asif!CT15+sumair!CT15 -> 0 | BV15: =Asghar!CX15+shahzad!CX15+Fahad!CX15+Asif!CX15+sumair!CX15 -> 0 | BW15: =Asghar!DB15+shahzad!DB15+Fahad!DB15+Asif!DB15+sumair!DB15 -> 0 | BX15: =Asghar!DF15+shahzad!DF15+Fahad!DF15+Asif!DF15+sumair!DF15 -> 0 | BY15: =Asghar!DJ15+shahzad!DJ15+Fahad!DJ15+Asif!DJ15+sumair!DJ15 -> 0 | BZ15: =Asghar!DN15+shahzad!DN15+Fahad!DN15+Asif!DN15+sumair!DN15 -> 0 | CA15: =Asghar!DR15+shahzad!DR15+Fahad!DR15+Asif!DR15+sumair!DR15 -> 0 | CB15: =Asghar!DV15+shahzad!DV15+Fahad!DV15+Asif!DV15+sumair!DV15 -> 0 | CC15: =Asghar!DZ15+shahzad!DZ15+Fahad!DZ15+Asif!DZ15+sumair!DZ15 -> 0 | CD15: =SUM(AY15:CC15) -> 0 | CF15: =N15 -> 7.5555556 | CG15: =AW15 -> 0 | CH15: =CG15+CF15 -> 7.5555556 | CI15: =CD15 -> 0 | CJ15: =CH15-CI15 -> 7.5555556
B16: 101930 | C16: PREMIUM PEACH RING JELLY RS 50 12BGX8BX | D16: 12 | E16: 8 | F16: 481.13468 | H16: 9 | I16: 4 | L16: =I16/E16 -> 0.5 | M16: =I16/E16 -> 0.5 | N16: =M16+H16 -> 9.5 | O16: =N16*E16 -> 76 | P16: =O16*F16 -> 36566.235 | AW16: =SUM(R16:AV16) -> 0 | AY16: =Asghar!J16+shahzad!J16+Fahad!J16+Asif!J16+sumair!J16 -> 0 | AZ16: =Asghar!N16+shahzad!N16+Fahad!N16+Asif!N16+sumair!N16 -> 0 | BA16: =Asghar!R16+shahzad!R16+Fahad!R16+Asif!R16+sumair!R16 -> 0 | BB16: =Asghar!V16+shahzad!V16+Fahad!V16+Asif!V16+sumair!V16 -> 0 | BC16: =Asghar!Z16+shahzad!Z16+Fahad!Z16+Asif!Z16+sumair!Z16 -> 0 | BD16: =Asghar!AD16+shahzad!AD16+Fahad!AD16+Asif!AD16+sumair!AD16 -> 0 | BE16: =Asghar!AH16+shahzad!AH16+Fahad!AH16+Asif!AH16+sumair!AH16 -> 0 | BF16: =Asghar!AL16+shahzad!AL16+Fahad!AL16+Asif!AL16+sumair!AL16 -> 0 | BG16: =Asghar!AP16+shahzad!AP16+Fahad!AP16+Asif!AP16+sumair!AP16 -> 0 | BH16: =Asghar!AT16+shahzad!AT16+Fahad!AT16+Asif!AT16+sumair!AT16 -> 0 | BI16: =Asghar!AX16+shahzad!AX16+Fahad!AX16+Asif!AX16+sumair!AX16 -> 0 | BJ16: =Asghar!BB16+shahzad!BB16+Fahad!BB16+Asif!BB16+sumair!BB16 -> 0 | BK16: =Asghar!BF16+shahzad!BF16+Fahad!BF16+Asif!BF16+sumair!BF16 -> 0 | BL16: =Asghar!BJ16+shahzad!BJ16+Fahad!BJ16+Asif!BJ16+sumair!BJ16 -> 0 | BM16: =Asghar!BN16+shahzad!BN16+Fahad!BN16+Asif!BN16+sumair!BN16 -> 0 | BN16: =Asghar!BR16+shahzad!BR16+Fahad!BR16+Asif!BR16+sumair!BR16 -> 0 | BO16: =Asghar!BV16+shahzad!BV16+Fahad!BV16+Asif!BV16+sumair!BV16 -> 0 | BP16: =Asghar!BZ16+shahzad!BZ16+Fahad!BZ16+Asif!BZ16+sumair!BZ16 -> 0 | BQ16: =Asghar!CD16+shahzad!CD16+Fahad!CD16+Asif!CD16+sumair!CD16 -> 0 | BR16: =Asghar!CH16+shahzad!CH16+Fahad!CH16+Asif!CH16+sumair!CH16 -> 0 | BS16: =Asghar!CL16+shahzad!CL16+Fahad!CL16+Asif!CL16+sumair!CL16 -> 0 | BT16: =Asghar!CP16+shahzad!CP16+Fahad!CP16+Asif!CP16+sumair!CP16 -> 0 | BU16: =Asghar!CT16+shahzad!CT16+Fahad!CT16+Asif!CT16+sumair!CT16 -> 0 | BV16: =Asghar!CX16+shahzad!CX16+Fahad!CX16+Asif!CX16+sumair!CX16 -> 0 | BW16: =Asghar!DB16+shahzad!DB16+Fahad!DB16+Asif!DB16+sumair!DB16 -> 0 | BX16: =Asghar!DF16+shahzad!DF16+Fahad!DF16+Asif!DF16+sumair!DF16 -> 0 | BY16: =Asghar!DJ16+shahzad!DJ16+Fahad!DJ16+Asif!DJ16+sumair!DJ16 -> 0 | BZ16: =Asghar!DN16+shahzad!DN16+Fahad!DN16+Asif!DN16+sumair!DN16 -> 0 | CA16: =Asghar!DR16+shahzad!DR16+Fahad!DR16+Asif!DR16+sumair!DR16 -> 0 | CB16: =Asghar!DV16+shahzad!DV16+Fahad!DV16+Asif!DV16+sumair!DV16 -> 0 | CC16: =Asghar!DZ16+shahzad!DZ16+Fahad!DZ16+Asif!DZ16+sumair!DZ16 -> 0 | CD16: =SUM(AY16:CC16) -> 0 | CF16: =N16 -> 9.5 | CG16: =AW16 -> 0 | CH16: =CG16+CF16 -> 9.5 | CI16: =CD16 -> 0 | CJ16: =CH16-CI16 -> 9.5
B17: 101931 | C17: PREMIUM WATERMELON JELLY RS50 12BGX8BX | D17: 12 | E17: 8 | F17: 481.13468 | H17: 19 | I17: 5 | L17: =I17/E17 -> 0.625 | M17: =I17/E17 -> 0.625 | N17: =M17+H17 -> 19.625 | O17: =N17*E17 -> 157 | P17: =O17*F17 -> 75538.144 | AW17: =SUM(R17:AV17) -> 0 | AY17: =Asghar!J17+shahzad!J17+Fahad!J17+Asif!J17+sumair!J17 -> 0 | AZ17: =Asghar!N17+shahzad!N17+Fahad!N17+Asif!N17+sumair!N17 -> 0 | BA17: =Asghar!R17+shahzad!R17+Fahad!R17+Asif!R17+sumair!R17 -> 0 | BB17: =Asghar!V17+shahzad!V17+Fahad!V17+Asif!V17+sumair!V17 -> 0 | BC17: =Asghar!Z17+shahzad!Z17+Fahad!Z17+Asif!Z17+sumair!Z17 -> 0 | BD17: =Asghar!AD17+shahzad!AD17+Fahad!AD17+Asif!AD17+sumair!AD17 -> 0 | BE17: =Asghar!AH17+shahzad!AH17+Fahad!AH17+Asif!AH17+sumair!AH17 -> 0 | BF17: =Asghar!AL17+shahzad!AL17+Fahad!AL17+Asif!AL17+sumair!AL17 -> 0 | BG17: =Asghar!AP17+shahzad!AP17+Fahad!AP17+Asif!AP17+sumair!AP17 -> 0 | BH17: =Asghar!AT17+shahzad!AT17+Fahad!AT17+Asif!AT17+sumair!AT17 -> 0 | BI17: =Asghar!AX17+shahzad!AX17+Fahad!AX17+Asif!AX17+sumair!AX17 -> 0 | BJ17: =Asghar!BB17+shahzad!BB17+Fahad!BB17+Asif!BB17+sumair!BB17 -> 0 | BK17: =Asghar!BF17+shahzad!BF17+Fahad!BF17+Asif!BF17+sumair!BF17 -> 0 | BL17: =Asghar!BJ17+shahzad!BJ17+Fahad!BJ17+Asif!BJ17+sumair!BJ17 -> 0 | BM17: =Asghar!BN17+shahzad!BN17+Fahad!BN17+Asif!BN17+sumair!BN17 -> 0 | BN17: =Asghar!BR17+shahzad!BR17+Fahad!BR17+Asif!BR17+sumair!BR17 -> 0 | BO17: =Asghar!BV17+shahzad!BV17+Fahad!BV17+Asif!BV17+sumair!BV17 -> 0 | BP17: =Asghar!BZ17+shahzad!BZ17+Fahad!BZ17+Asif!BZ17+sumair!BZ17 -> 0 | BQ17: =Asghar!CD17+shahzad!CD17+Fahad!CD17+Asif!CD17+sumair!CD17 -> 0 | BR17: =Asghar!CH17+shahzad!CH17+Fahad!CH17+Asif!CH17+sumair!CH17 -> 0 | BS17: =Asghar!CL17+shahzad!CL17+Fahad!CL17+Asif!CL17+sumair!CL17 -> 0 | BT17: =Asghar!CP17+shahzad!CP17+Fahad!CP17+Asif!CP17+sumair!CP17 -> 0 | BU17: =Asghar!CT17+shahzad!CT17+Fahad!CT17+Asif!CT17+sumair!CT17 -> 0 | BV17: =Asghar!CX17+shahzad!CX17+Fahad!CX17+Asif!CX17+sumair!CX17 -> 0 | BW17: =Asghar!DB17+shahzad!DB17+Fahad!DB17+Asif!DB17+sumair!DB17 -> 0 | BX17: =Asghar!DF17+shahzad!DF17+Fahad!DF17+Asif!DF17+sumair!DF17 -> 0 | BY17: =Asghar!DJ17+shahzad!DJ17+Fahad!DJ17+Asif!DJ17+sumair!DJ17 -> 0 | BZ17: =Asghar!DN17+shahzad!DN17+Fahad!DN17+Asif!DN17+sumair!DN17 -> 0 | CA17: =Asghar!DR17+shahzad!DR17+Fahad!DR17+Asif!DR17+sumair!DR17 -> 0 | CB17: =Asghar!DV17+shahzad!DV17+Fahad!DV17+Asif!DV17+sumair!DV17 -> 0 | CC17: =Asghar!DZ17+shahzad!DZ17+Fahad!DZ17+Asif!DZ17+sumair!DZ17 -> 0 | CD17: =SUM(AY17:CC17) -> 0 | CF17: =N17 -> 19.625 | CG17: =AW17 -> 0 | CH17: =CG17+CF17 -> 19.625 | CI17: =CD17 -> 0 | CJ17: =CH17-CI17 -> 19.625
B18: 101932 | C18: PREMIUM NEON CRAWLER JELY RS50 12BGX8BX | D18: 12 | E18: 8 | F18: 481.13468 | I18: 7 | L18: =I18/E18 -> 0.875 | M18: =I18/E18 -> 0.875 | N18: =M18+H18 -> 0.875 | O18: =N18*E18 -> 7 | P18: =O18*F18 -> 3367.9427 | AW18: =SUM(R18:AV18) -> 0 | AY18: =Asghar!J18+shahzad!J18+Fahad!J18+Asif!J18+sumair!J18 -> 0 | AZ18: =Asghar!N18+shahzad!N18+Fahad!N18+Asif!N18+sumair!N18 -> 0 | BA18: =Asghar!R18+shahzad!R18+Fahad!R18+Asif!R18+sumair!R18 -> 0 | BB18: =Asghar!V18+shahzad!V18+Fahad!V18+Asif!V18+sumair!V18 -> 0 | BC18: =Asghar!Z18+shahzad!Z18+Fahad!Z18+Asif!Z18+sumair!Z18 -> 0 | BD18: =Asghar!AD18+shahzad!AD18+Fahad!AD18+Asif!AD18+sumair!AD18 -> 0 | BE18: =Asghar!AH18+shahzad!AH18+Fahad!AH18+Asif!AH18+sumair!AH18 -> 0 | BF18: =Asghar!AL18+shahzad!AL18+Fahad!AL18+Asif!AL18+sumair!AL18 -> 0 | BG18: =Asghar!AP18+shahzad!AP18+Fahad!AP18+Asif!AP18+sumair!AP18 -> 0 | BH18: =Asghar!AT18+shahzad!AT18+Fahad!AT18+Asif!AT18+sumair!AT18 -> 0 | BI18: =Asghar!AX18+shahzad!AX18+Fahad!AX18+Asif!AX18+sumair!AX18 -> 0 | BJ18: =Asghar!BB18+shahzad!BB18+Fahad!BB18+Asif!BB18+sumair!BB18 -> 0 | BK18: =Asghar!BF18+shahzad!BF18+Fahad!BF18+Asif!BF18+sumair!BF18 -> 0 | BL18: =Asghar!BJ18+shahzad!BJ18+Fahad!BJ18+Asif!BJ18+sumair!BJ18 -> 0 | BM18: =Asghar!BN18+shahzad!BN18+Fahad!BN18+Asif!BN18+sumair!BN18 -> 0 | BN18: =Asghar!BR18+shahzad!BR18+Fahad!BR18+Asif!BR18+sumair!BR18 -> 0 | BO18: =Asghar!BV18+shahzad!BV18+Fahad!BV18+Asif!BV18+sumair!BV18 -> 0 | BP18: =Asghar!BZ18+shahzad!BZ18+Fahad!BZ18+Asif!BZ18+sumair!BZ18 -> 0 | BQ18: =Asghar!CD18+shahzad!CD18+Fahad!CD18+Asif!CD18+sumair!CD18 -> 0 | BR18: =Asghar!CH18+shahzad!CH18+Fahad!CH18+Asif!CH18+sumair!CH18 -> 0 | BS18: =Asghar!CL18+shahzad!CL18+Fahad!CL18+Asif!CL18+sumair!CL18 -> 0 | BT18: =Asghar!CP18+shahzad!CP18+Fahad!CP18+Asif!CP18+sumair!CP18 -> 0 | BU18: =Asghar!CT18+shahzad!CT18+Fahad!CT18+Asif!CT18+sumair!CT18 -> 0 | BV18: =Asghar!CX18+shahzad!CX18+Fahad!CX18+Asif!CX18+sumair!CX18 -> 0 | BW18: =Asghar!DB18+shahzad!DB18+Fahad!DB18+Asif!DB18+sumair!DB18 -> 0 | BX18: =Asghar!DF18+shahzad!DF18+Fahad!DF18+Asif!DF18+sumair!DF18 -> 0 | BY18: =Asghar!DJ18+shahzad!DJ18+Fahad!DJ18+Asif!DJ18+sumair!DJ18 -> 0 | BZ18: =Asghar!DN18+shahzad!DN18+Fahad!DN18+Asif!DN18+sumair!DN18 -> 0 | CA18: =Asghar!DR18+shahzad!DR18+Fahad!DR18+Asif!DR18+sumair!DR18 -> 0 | CB18: =Asghar!DV18+shahzad!DV18+Fahad!DV18+Asif!DV18+sumair!DV18 -> 0 | CC18: =Asghar!DZ18+shahzad!DZ18+Fahad!DZ18+Asif!DZ18+sumair!DZ18 -> 0 | CD18: =SUM(AY18:CC18) -> 0 | CF18: =N18 -> 0.875 | CG18: =AW18 -> 0 | CH18: =CG18+CF18 -> 0.875 | CI18: =CD18 -> 0 | CJ18: =CH18-CI18 -> 0.875
B19: 101933 | C19: PREMIUM COLA BOTTLE JELY RS50 12BGX8BX | D19: 12 | E19: 8 | F19: 481.13468 | H19: 18 | I19: 2 | L19: =I19/E19 -> 0.25 | M19: =I19/E19 -> 0.25 | N19: =M19+H19 -> 18.25 | O19: =N19*E19 -> 146 | P19: =O19*F19 -> 70245.663 | AW19: =SUM(R19:AV19) -> 0 | AY19: =Asghar!J19+shahzad!J19+Fahad!J19+Asif!J19+sumair!J19 -> 0 | AZ19: =Asghar!N19+shahzad!N19+Fahad!N19+Asif!N19+sumair!N19 -> 0 | BA19: =Asghar!R19+shahzad!R19+Fahad!R19+Asif!R19+sumair!R19 -> 0 | BB19: =Asghar!V19+shahzad!V19+Fahad!V19+Asif!V19+sumair!V19 -> 0 | BC19: =Asghar!Z19+shahzad!Z19+Fahad!Z19+Asif!Z19+sumair!Z19 -> 0 | BD19: =Asghar!AD19+shahzad!AD19+Fahad!AD19+Asif!AD19+sumair!AD19 -> 0 | BE19: =Asghar!AH19+shahzad!AH19+Fahad!AH19+Asif!AH19+sumair!AH19 -> 0 | BF19: =Asghar!AL19+shahzad!AL19+Fahad!AL19+Asif!AL19+sumair!AL19 -> 0 | BG19: =Asghar!AP19+shahzad!AP19+Fahad!AP19+Asif!AP19+sumair!AP19 -> 0 | BH19: =Asghar!AT19+shahzad!AT19+Fahad!AT19+Asif!AT19+sumair!AT19 -> 0 | BI19: =Asghar!AX19+shahzad!AX19+Fahad!AX19+Asif!AX19+sumair!AX19 -> 0 | BJ19: =Asghar!BB19+shahzad!BB19+Fahad!BB19+Asif!BB19+sumair!BB19 -> 0 | BK19: =Asghar!BF19+shahzad!BF19+Fahad!BF19+Asif!BF19+sumair!BF19 -> 0 | BL19: =Asghar!BJ19+shahzad!BJ19+Fahad!BJ19+Asif!BJ19+sumair!BJ19 -> 0 | BM19: =Asghar!BN19+shahzad!BN19+Fahad!BN19+Asif!BN19+sumair!BN19 -> 0 | BN19: =Asghar!BR19+shahzad!BR19+Fahad!BR19+Asif!BR19+sumair!BR19 -> 0 | BO19: =Asghar!BV19+shahzad!BV19+Fahad!BV19+Asif!BV19+sumair!BV19 -> 0 | BP19: =Asghar!BZ19+shahzad!BZ19+Fahad!BZ19+Asif!BZ19+sumair!BZ19 -> 0 | BQ19: =Asghar!CD19+shahzad!CD19+Fahad!CD19+Asif!CD19+sumair!CD19 -> 0 | BR19: =Asghar!CH19+shahzad!CH19+Fahad!CH19+Asif!CH19+sumair!CH19 -> 0 | BS19: =Asghar!CL19+shahzad!CL19+Fahad!CL19+Asif!CL19+sumair!CL19 -> 0 | BT19: =Asghar!CP19+shahzad!CP19+Fahad!CP19+Asif!CP19+sumair!CP19 -> 0 | BU19: =Asghar!CT19+shahzad!CT19+Fahad!CT19+Asif!CT19+sumair!CT19 -> 0 | BV19: =Asghar!CX19+shahzad!CX19+Fahad!CX19+Asif!CX19+sumair!CX19 -> 0 | BW19: =Asghar!DB19+shahzad!DB19+Fahad!DB19+Asif!DB19+sumair!DB19 -> 0 | BX19: =Asghar!DF19+shahzad!DF19+Fahad!DF19+Asif!DF19+sumair!DF19 -> 0 | BY19: =Asghar!DJ19+shahzad!DJ19+Fahad!DJ19+Asif!DJ19+sumair!DJ19 -> 0 | BZ19: =Asghar!DN19+shahzad!DN19+Fahad!DN19+Asif!DN19+sumair!DN19 -> 0 | CA19: =Asghar!DR19+shahzad!DR19+Fahad!DR19+Asif!DR19+sumair!DR19 -> 0 | CB19: =Asghar!DV19+shahzad!DV19+Fahad!DV19+Asif!DV19+sumair!DV19 -> 0 | CC19: =Asghar!DZ19+shahzad!DZ19+Fahad!DZ19+Asif!DZ19+sumair!DZ19 -> 0 | CD19: =SUM(AY19:CC19) -> 0 | CF19: =N19 -> 18.25 | CG19: =AW19 -> 0 | CH19: =CG19+CF19 -> 18.25 | CI19: =CD19 -> 0 | CJ19: =CH19-CI19 -> 18.25
B20: 101934 | C20: Mango - Premium - Rs. 50 - (12X8) - Box | D20: 12 | E20: 8 | F20: 481.13468 | L20: =I20/E20 -> 0 | M20: =I20/E20 -> 0 | N20: =M20+H20 -> 0 | O20: =N20*E20 -> 0 | P20: =O20*F20 -> 0 | AW20: =SUM(R20:AV20) -> 0 | AY20: =Asghar!J20+shahzad!J20+Fahad!J20+Asif!J20+sumair!J20 -> 0 | AZ20: =Asghar!N20+shahzad!N20+Fahad!N20+Asif!N20+sumair!N20 -> 0 | BA20: =Asghar!R20+shahzad!R20+Fahad!R20+Asif!R20+sumair!R20 -> 0 | BB20: =Asghar!V20+shahzad!V20+Fahad!V20+Asif!V20+sumair!V20 -> 0 | BC20: =Asghar!Z20+shahzad!Z20+Fahad!Z20+Asif!Z20+sumair!Z20 -> 0 | BD20: =Asghar!AD20+shahzad!AD20+Fahad!AD20+Asif!AD20+sumair!AD20 -> 0 | BE20: =Asghar!AH20+shahzad!AH20+Fahad!AH20+Asif!AH20+sumair!AH20 -> 0 | BF20: =Asghar!AL20+shahzad!AL20+Fahad!AL20+Asif!AL20+sumair!AL20 -> 0 | BG20: =Asghar!AP20+shahzad!AP20+Fahad!AP20+Asif!AP20+sumair!AP20 -> 0 | BH20: =Asghar!AT20+shahzad!AT20+Fahad!AT20+Asif!AT20+sumair!AT20 -> 0 | BI20: =Asghar!AX20+shahzad!AX20+Fahad!AX20+Asif!AX20+sumair!AX20 -> 0 | BJ20: =Asghar!BB20+shahzad!BB20+Fahad!BB20+Asif!BB20+sumair!BB20 -> 0 | BK20: =Asghar!BF20+shahzad!BF20+Fahad!BF20+Asif!BF20+sumair!BF20 -> 0 | BL20: =Asghar!BJ20+shahzad!BJ20+Fahad!BJ20+Asif!BJ20+sumair!BJ20 -> 0 | BM20: =Asghar!BN20+shahzad!BN20+Fahad!BN20+Asif!BN20+sumair!BN20 -> 0 | BN20: =Asghar!BR20+shahzad!BR20+Fahad!BR20+Asif!BR20+sumair!BR20 -> 0 | BO20: =Asghar!BV20+shahzad!BV20+Fahad!BV20+Asif!BV20+sumair!BV20 -> 0 | BP20: =Asghar!BZ20+shahzad!BZ20+Fahad!BZ20+Asif!BZ20+sumair!BZ20 -> 0 | BQ20: =Asghar!CD20+shahzad!CD20+Fahad!CD20+Asif!CD20+sumair!CD20 -> 0 | BR20: =Asghar!CH20+shahzad!CH20+Fahad!CH20+Asif!CH20+sumair!CH20 -> 0 | BS20: =Asghar!CL20+shahzad!CL20+Fahad!CL20+Asif!CL20+sumair!CL20 -> 0 | BT20: =Asghar!CP20+shahzad!CP20+Fahad!CP20+Asif!CP20+sumair!CP20 -> 0 | BU20: =Asghar!CT20+shahzad!CT20+Fahad!CT20+Asif!CT20+sumair!CT20 -> 0 | BV20: =Asghar!CX20+shahzad!CX20+Fahad!CX20+Asif!CX20+sumair!CX20 -> 0 | BW20: =Asghar!DB20+shahzad!DB20+Fahad!DB20+Asif!DB20+sumair!DB20 -> 0 | BX20: =Asghar!DF20+shahzad!DF20+Fahad!DF20+Asif!DF20+sumair!DF20 -> 0 | BY20: =Asghar!DJ20+shahzad!DJ20+Fahad!DJ20+Asif!DJ20+sumair!DJ20 -> 0 | BZ20: =Asghar!DN20+shahzad!DN20+Fahad!DN20+Asif!DN20+sumair!DN20 -> 0 | CA20: =Asghar!DR20+shahzad!DR20+Fahad!DR20+Asif!DR20+sumair!DR20 -> 0 | CB20: =Asghar!DV20+shahzad!DV20+Fahad!DV20+Asif!DV20+sumair!DV20 -> 0 | CC20: =Asghar!DZ20+shahzad!DZ20+Fahad!DZ20+Asif!DZ20+sumair!DZ20 -> 0 | CD20: =SUM(AY20:CC20) -> 0 | CF20: =N20 -> 0 | CG20: =AW20 -> 0 | CH20: =CG20+CF20 -> 0 | CI20: =CD20 -> 0 | CJ20: =CH20-CI20 -> 0
B21: 102155 | C21: BUBBLE YOUR NAME RS 5 100 PC/JARX12 JARS | D21: 1 | E21: 12 | F21: 394.37248 | H21: 5 | I21: 10 | L21: =I21/E21 -> 0.83333333 | M21: =I21/E21 -> 0.83333333 | N21: =M21+H21 -> 5.8333333 | O21: =N21*E21 -> 70 | P21: =O21*F21 -> 27606.074 | AW21: =SUM(R21:AV21) -> 0 | AY21: =Asghar!J21+shahzad!J21+Fahad!J21+Asif!J21+sumair!J21 -> 0 | AZ21: =Asghar!N21+shahzad!N21+Fahad!N21+Asif!N21+sumair!N21 -> 0 | BA21: =Asghar!R21+shahzad!R21+Fahad!R21+Asif!R21+sumair!R21 -> 0 | BB21: =Asghar!V21+shahzad!V21+Fahad!V21+Asif!V21+sumair!V21 -> 0 | BC21: =Asghar!Z21+shahzad!Z21+Fahad!Z21+Asif!Z21+sumair!Z21 -> 0 | BD21: =Asghar!AD21+shahzad!AD21+Fahad!AD21+Asif!AD21+sumair!AD21 -> 0 | BE21: =Asghar!AH21+shahzad!AH21+Fahad!AH21+Asif!AH21+sumair!AH21 -> 0 | BF21: =Asghar!AL21+shahzad!AL21+Fahad!AL21+Asif!AL21+sumair!AL21 -> 0 | BG21: =Asghar!AP21+shahzad!AP21+Fahad!AP21+Asif!AP21+sumair!AP21 -> 0 | BH21: =Asghar!AT21+shahzad!AT21+Fahad!AT21+Asif!AT21+sumair!AT21 -> 0 | BI21: =Asghar!AX21+shahzad!AX21+Fahad!AX21+Asif!AX21+sumair!AX21 -> 0 | BJ21: =Asghar!BB21+shahzad!BB21+Fahad!BB21+Asif!BB21+sumair!BB21 -> 0 | BK21: =Asghar!BF21+shahzad!BF21+Fahad!BF21+Asif!BF21+sumair!BF21 -> 0 | BL21: =Asghar!BJ21+shahzad!BJ21+Fahad!BJ21+Asif!BJ21+sumair!BJ21 -> 0 | BM21: =Asghar!BN21+shahzad!BN21+Fahad!BN21+Asif!BN21+sumair!BN21 -> 0 | BN21: =Asghar!BR21+shahzad!BR21+Fahad!BR21+Asif!BR21+sumair!BR21 -> 0 | BO21: =Asghar!BV21+shahzad!BV21+Fahad!BV21+Asif!BV21+sumair!BV21 -> 0 | BP21: =Asghar!BZ21+shahzad!BZ21+Fahad!BZ21+Asif!BZ21+sumair!BZ21 -> 0 | BQ21: =Asghar!CD21+shahzad!CD21+Fahad!CD21+Asif!CD21+sumair!CD21 -> 0 | BR21: =Asghar!CH21+shahzad!CH21+Fahad!CH21+Asif!CH21+sumair!CH21 -> 0 | BS21: =Asghar!CL21+shahzad!CL21+Fahad!CL21+Asif!CL21+sumair!CL21 -> 0 | BT21: =Asghar!CP21+shahzad!CP21+Fahad!CP21+Asif!CP21+sumair!CP21 -> 0 | BU21: =Asghar!CT21+shahzad!CT21+Fahad!CT21+Asif!CT21+sumair!CT21 -> 0 | BV21: =Asghar!CX21+shahzad!CX21+Fahad!CX21+Asif!CX21+sumair!CX21 -> 0 | BW21: =Asghar!DB21+shahzad!DB21+Fahad!DB21+Asif!DB21+sumair!DB21 -> 0 | BX21: =Asghar!DF21+shahzad!DF21+Fahad!DF21+Asif!DF21+sumair!DF21 -> 0 | BY21: =Asghar!DJ21+shahzad!DJ21+Fahad!DJ21+Asif!DJ21+sumair!DJ21 -> 0 | BZ21: =Asghar!DN21+shahzad!DN21+Fahad!DN21+Asif!DN21+sumair!DN21 -> 0 | CA21: =Asghar!DR21+shahzad!DR21+Fahad!DR21+Asif!DR21+sumair!DR21 -> 0 | CB21: =Asghar!DV21+shahzad!DV21+Fahad!DV21+Asif!DV21+sumair!DV21 -> 0 | CC21: =Asghar!DZ21+shahzad!DZ21+Fahad!DZ21+Asif!DZ21+sumair!DZ21 -> 0 | CD21: =SUM(AY21:CC21) -> 0 | CF21: =N21 -> 5.8333333 | CG21: =AW21 -> 0 | CH21: =CG21+CF21 -> 5.8333333 | CI21: =CD21 -> 0 | CJ21: =CH21-CI21 -> 5.8333333
B22: 102157 | C22: Bubble Yr Name - Rs. 5 - (50 x 18) - Box | D22: 50 | E22: 18 | F22: 200.47282 | H22: 4 | I22: 9 | L22: =I22/E22 -> 0.5 | M22: =I22/E22 -> 0.5 | N22: =M22+H22 -> 4.5 | O22: =N22*E22 -> 81 | P22: =O22*F22 -> 16238.299 | AW22: =SUM(R22:AV22) -> 0 | AY22: =Asghar!J22+shahzad!J22+Fahad!J22+Asif!J22+sumair!J22 -> 0 | AZ22: =Asghar!N22+shahzad!N22+Fahad!N22+Asif!N22+sumair!N22 -> 0 | BA22: =Asghar!R22+shahzad!R22+Fahad!R22+Asif!R22+sumair!R22 -> 0 | BB22: =Asghar!V22+shahzad!V22+Fahad!V22+Asif!V22+sumair!V22 -> 0 | BC22: =Asghar!Z22+shahzad!Z22+Fahad!Z22+Asif!Z22+sumair!Z22 -> 0 | BD22: =Asghar!AD22+shahzad!AD22+Fahad!AD22+Asif!AD22+sumair!AD22 -> 0 | BE22: =Asghar!AH22+shahzad!AH22+Fahad!AH22+Asif!AH22+sumair!AH22 -> 0 | BF22: =Asghar!AL22+shahzad!AL22+Fahad!AL22+Asif!AL22+sumair!AL22 -> 0 | BG22: =Asghar!AP22+shahzad!AP22+Fahad!AP22+Asif!AP22+sumair!AP22 -> 0 | BH22: =Asghar!AT22+shahzad!AT22+Fahad!AT22+Asif!AT22+sumair!AT22 -> 0 | BI22: =Asghar!AX22+shahzad!AX22+Fahad!AX22+Asif!AX22+sumair!AX22 -> 0 | BJ22: =Asghar!BB22+shahzad!BB22+Fahad!BB22+Asif!BB22+sumair!BB22 -> 0 | BK22: =Asghar!BF22+shahzad!BF22+Fahad!BF22+Asif!BF22+sumair!BF22 -> 0 | BL22: =Asghar!BJ22+shahzad!BJ22+Fahad!BJ22+Asif!BJ22+sumair!BJ22 -> 0 | BM22: =Asghar!BN22+shahzad!BN22+Fahad!BN22+Asif!BN22+sumair!BN22 -> 0 | BN22: =Asghar!BR22+shahzad!BR22+Fahad!BR22+Asif!BR22+sumair!BR22 -> 0 | BO22: =Asghar!BV22+shahzad!BV22+Fahad!BV22+Asif!BV22+sumair!BV22 -> 0 | BP22: =Asghar!BZ22+shahzad!BZ22+Fahad!BZ22+Asif!BZ22+sumair!BZ22 -> 0 | BQ22: =Asghar!CD22+shahzad!CD22+Fahad!CD22+Asif!CD22+sumair!CD22 -> 0 | BR22: =Asghar!CH22+shahzad!CH22+Fahad!CH22+Asif!CH22+sumair!CH22 -> 0 | BS22: =Asghar!CL22+shahzad!CL22+Fahad!CL22+Asif!CL22+sumair!CL22 -> 0 | BT22: =Asghar!CP22+shahzad!CP22+Fahad!CP22+Asif!CP22+sumair!CP22 -> 0 | BU22: =Asghar!CT22+shahzad!CT22+Fahad!CT22+Asif!CT22+sumair!CT22 -> 0 | BV22: =Asghar!CX22+shahzad!CX22+Fahad!CX22+Asif!CX22+sumair!CX22 -> 0 | BW22: =Asghar!DB22+shahzad!DB22+Fahad!DB22+Asif!DB22+sumair!DB22 -> 0 | BX22: =Asghar!DF22+shahzad!DF22+Fahad!DF22+Asif!DF22+sumair!DF22 -> 0 | BY22: =Asghar!DJ22+shahzad!DJ22+Fahad!DJ22+Asif!DJ22+sumair!DJ22 -> 0 | BZ22: =Asghar!DN22+shahzad!DN22+Fahad!DN22+Asif!DN22+sumair!DN22 -> 0 | CA22: =Asghar!DR22+shahzad!DR22+Fahad!DR22+Asif!DR22+sumair!DR22 -> 0 | CB22: =Asghar!DV22+shahzad!DV22+Fahad!DV22+Asif!DV22+sumair!DV22 -> 0 | CC22: =Asghar!DZ22+shahzad!DZ22+Fahad!DZ22+Asif!DZ22+sumair!DZ22 -> 0 | CD22: =SUM(AY22:CC22) -> 0 | CF22: =N22 -> 4.5 | CG22: =AW22 -> 0 | CH22: =CG22+CF22 -> 4.5 | CI22: =CD22 -> 0 | CJ22: =CH22-CI22 -> 4.5
B23: 102926 | C23: BUBBLE POP GUM RS 5 50 PC X 18 BOX | D23: 50 | E23: 18 | F23: 197.18624 | H23: 68 | L23: =I23/E23 -> 0 | M23: =I23/E23 -> 0 | N23: =M23+H23 -> 68 | O23: =N23*E23 -> 1224 | P23: =O23*F23 -> 241355.96 | AW23: =SUM(R23:AV23) -> 0 | AY23: =Asghar!J23+shahzad!J23+Fahad!J23+Asif!J23+sumair!J23 -> 0 | AZ23: =Asghar!N23+shahzad!N23+Fahad!N23+Asif!N23+sumair!N23 -> 0 | BA23: =Asghar!R23+shahzad!R23+Fahad!R23+Asif!R23+sumair!R23 -> 0 | BB23: =Asghar!V23+shahzad!V23+Fahad!V23+Asif!V23+sumair!V23 -> 0 | BC23: =Asghar!Z23+shahzad!Z23+Fahad!Z23+Asif!Z23+sumair!Z23 -> 0 | BD23: =Asghar!AD23+shahzad!AD23+Fahad!AD23+Asif!AD23+sumair!AD23 -> 0 | BE23: =Asghar!AH23+shahzad!AH23+Fahad!AH23+Asif!AH23+sumair!AH23 -> 0 | BF23: =Asghar!AL23+shahzad!AL23+Fahad!AL23+Asif!AL23+sumair!AL23 -> 0 | BG23: =Asghar!AP23+shahzad!AP23+Fahad!AP23+Asif!AP23+sumair!AP23 -> 0 | BH23: =Asghar!AT23+shahzad!AT23+Fahad!AT23+Asif!AT23+sumair!AT23 -> 0 | BI23: =Asghar!AX23+shahzad!AX23+Fahad!AX23+Asif!AX23+sumair!AX23 -> 0 | BJ23: =Asghar!BB23+shahzad!BB23+Fahad!BB23+Asif!BB23+sumair!BB23 -> 0 | BK23: =Asghar!BF23+shahzad!BF23+Fahad!BF23+Asif!BF23+sumair!BF23 -> 0 | BL23: =Asghar!BJ23+shahzad!BJ23+Fahad!BJ23+Asif!BJ23+sumair!BJ23 -> 0 | BM23: =Asghar!BN23+shahzad!BN23+Fahad!BN23+Asif!BN23+sumair!BN23 -> 0 | BN23: =Asghar!BR23+shahzad!BR23+Fahad!BR23+Asif!BR23+sumair!BR23 -> 0 | BO23: =Asghar!BV23+shahzad!BV23+Fahad!BV23+Asif!BV23+sumair!BV23 -> 0 | BP23: =Asghar!BZ23+shahzad!BZ23+Fahad!BZ23+Asif!BZ23+sumair!BZ23 -> 0 | BQ23: =Asghar!CD23+shahzad!CD23+Fahad!CD23+Asif!CD23+sumair!CD23 -> 0 | BR23: =Asghar!CH23+shahzad!CH23+Fahad!CH23+Asif!CH23+sumair!CH23 -> 0 | BS23: =Asghar!CL23+shahzad!CL23+Fahad!CL23+Asif!CL23+sumair!CL23 -> 0 | BT23: =Asghar!CP23+shahzad!CP23+Fahad!CP23+Asif!CP23+sumair!CP23 -> 0 | BU23: =Asghar!CT23+shahzad!CT23+Fahad!CT23+Asif!CT23+sumair!CT23 -> 0 | BV23: =Asghar!CX23+shahzad!CX23+Fahad!CX23+Asif!CX23+sumair!CX23 -> 0 | BW23: =Asghar!DB23+shahzad!DB23+Fahad!DB23+Asif!DB23+sumair!DB23 -> 0 | BX23: =Asghar!DF23+shahzad!DF23+Fahad!DF23+Asif!DF23+sumair!DF23 -> 0 | BY23: =Asghar!DJ23+shahzad!DJ23+Fahad!DJ23+Asif!DJ23+sumair!DJ23 -> 0 | BZ23: =Asghar!DN23+shahzad!DN23+Fahad!DN23+Asif!DN23+sumair!DN23 -> 0 | CA23: =Asghar!DR23+shahzad!DR23+Fahad!DR23+Asif!DR23+sumair!DR23 -> 0 | CB23: =Asghar!DV23+shahzad!DV23+Fahad!DV23+Asif!DV23+sumair!DV23 -> 0 | CC23: =Asghar!DZ23+shahzad!DZ23+Fahad!DZ23+Asif!DZ23+sumair!DZ23 -> 0 | CD23: =SUM(AY23:CC23) -> 0 | CF23: =N23 -> 68 | CG23: =AW23 -> 0 | CH23: =CG23+CF23 -> 68 | CI23: =CD23 -> 0 | CJ23: =CH23-CI23 -> 68
B24: 102929 | C24: Bubble Pop Classic -Rs.5-(50x18) - Box | D24: 50 | E24: 18 | F24: 200.47282 | H24: 16 | I24: 8 | L24: =I24/E24 -> 0.44444444 | M24: =I24/E24 -> 0.44444444 | N24: =M24+H24 -> 16.444444 | O24: =N24*E24 -> 296 | P24: =O24*F24 -> 59339.955 | AW24: =SUM(R24:AV24) -> 0 | AY24: =Asghar!J24+shahzad!J24+Fahad!J24+Asif!J24+sumair!J24 -> 0 | AZ24: =Asghar!N24+shahzad!N24+Fahad!N24+Asif!N24+sumair!N24 -> 0 | BA24: =Asghar!R24+shahzad!R24+Fahad!R24+Asif!R24+sumair!R24 -> 0 | BB24: =Asghar!V24+shahzad!V24+Fahad!V24+Asif!V24+sumair!V24 -> 0 | BC24: =Asghar!Z24+shahzad!Z24+Fahad!Z24+Asif!Z24+sumair!Z24 -> 0 | BD24: =Asghar!AD24+shahzad!AD24+Fahad!AD24+Asif!AD24+sumair!AD24 -> 0 | BE24: =Asghar!AH24+shahzad!AH24+Fahad!AH24+Asif!AH24+sumair!AH24 -> 0 | BF24: =Asghar!AL24+shahzad!AL24+Fahad!AL24+Asif!AL24+sumair!AL24 -> 0 | BG24: =Asghar!AP24+shahzad!AP24+Fahad!AP24+Asif!AP24+sumair!AP24 -> 0 | BH24: =Asghar!AT24+shahzad!AT24+Fahad!AT24+Asif!AT24+sumair!AT24 -> 0 | BI24: =Asghar!AX24+shahzad!AX24+Fahad!AX24+Asif!AX24+sumair!AX24 -> 0 | BJ24: =Asghar!BB24+shahzad!BB24+Fahad!BB24+Asif!BB24+sumair!BB24 -> 0 | BK24: =Asghar!BF24+shahzad!BF24+Fahad!BF24+Asif!BF24+sumair!BF24 -> 0 | BL24: =Asghar!BJ24+shahzad!BJ24+Fahad!BJ24+Asif!BJ24+sumair!BJ24 -> 0 | BM24: =Asghar!BN24+shahzad!BN24+Fahad!BN24+Asif!BN24+sumair!BN24 -> 0 | BN24: =Asghar!BR24+shahzad!BR24+Fahad!BR24+Asif!BR24+sumair!BR24 -> 0 | BO24: =Asghar!BV24+shahzad!BV24+Fahad!BV24+Asif!BV24+sumair!BV24 -> 0 | BP24: =Asghar!BZ24+shahzad!BZ24+Fahad!BZ24+Asif!BZ24+sumair!BZ24 -> 0 | BQ24: =Asghar!CD24+shahzad!CD24+Fahad!CD24+Asif!CD24+sumair!CD24 -> 0 | BR24: =Asghar!CH24+shahzad!CH24+Fahad!CH24+Asif!CH24+sumair!CH24 -> 0 | BS24: =Asghar!CL24+shahzad!CL24+Fahad!CL24+Asif!CL24+sumair!CL24 -> 0 | BT24: =Asghar!CP24+shahzad!CP24+Fahad!CP24+Asif!CP24+sumair!CP24 -> 0 | BU24: =Asghar!CT24+shahzad!CT24+Fahad!CT24+Asif!CT24+sumair!CT24 -> 0 | BV24: =Asghar!CX24+shahzad!CX24+Fahad!CX24+Asif!CX24+sumair!CX24 -> 0 | BW24: =Asghar!DB24+shahzad!DB24+Fahad!DB24+Asif!DB24+sumair!DB24 -> 0 | BX24: =Asghar!DF24+shahzad!DF24+Fahad!DF24+Asif!DF24+sumair!DF24 -> 0 | BY24: =Asghar!DJ24+shahzad!DJ24+Fahad!DJ24+Asif!DJ24+sumair!DJ24 -> 0 | BZ24: =Asghar!DN24+shahzad!DN24+Fahad!DN24+Asif!DN24+sumair!DN24 -> 0 | CA24: =Asghar!DR24+shahzad!DR24+Fahad!DR24+Asif!DR24+sumair!DR24 -> 0 | CB24: =Asghar!DV24+shahzad!DV24+Fahad!DV24+Asif!DV24+sumair!DV24 -> 0 | CC24: =Asghar!DZ24+shahzad!DZ24+Fahad!DZ24+Asif!DZ24+sumair!DZ24 -> 0 | CD24: =SUM(AY24:CC24) -> 0 | CF24: =N24 -> 16.444444 | CG24: =AW24 -> 0 | CH24: =CG24+CF24 -> 16.444444 | CI24: =CD24 -> 0 | CJ24: =CH24-CI24 -> 16.444444
B25: 103008 | C25: Dewy Chewy Strawberry-Rs.5-(50 x 18)-Jar | D25: 18 | E25: 18 | F25: 198.24262 | H25: 40 | I25: 12 | L25: =I25/E25 -> 0.66666667 | M25: =I25/E25 -> 0.66666667 | N25: =M25+H25 -> 40.666667 | O25: =N25*E25 -> 732 | P25: =O25*F25 -> 145113.6 | AW25: =SUM(R25:AV25) -> 0 | AY25: =Asghar!J25+shahzad!J25+Fahad!J25+Asif!J25+sumair!J25 -> 0 | AZ25: =Asghar!N25+shahzad!N25+Fahad!N25+Asif!N25+sumair!N25 -> 0 | BA25: =Asghar!R25+shahzad!R25+Fahad!R25+Asif!R25+sumair!R25 -> 0 | BB25: =Asghar!V25+shahzad!V25+Fahad!V25+Asif!V25+sumair!V25 -> 0 | BC25: =Asghar!Z25+shahzad!Z25+Fahad!Z25+Asif!Z25+sumair!Z25 -> 0 | BD25: =Asghar!AD25+shahzad!AD25+Fahad!AD25+Asif!AD25+sumair!AD25 -> 0 | BE25: =Asghar!AH25+shahzad!AH25+Fahad!AH25+Asif!AH25+sumair!AH25 -> 0 | BF25: =Asghar!AL25+shahzad!AL25+Fahad!AL25+Asif!AL25+sumair!AL25 -> 0 | BG25: =Asghar!AP25+shahzad!AP25+Fahad!AP25+Asif!AP25+sumair!AP25 -> 0 | BH25: =Asghar!AT25+shahzad!AT25+Fahad!AT25+Asif!AT25+sumair!AT25 -> 0 | BI25: =Asghar!AX25+shahzad!AX25+Fahad!AX25+Asif!AX25+sumair!AX25 -> 0 | BJ25: =Asghar!BB25+shahzad!BB25+Fahad!BB25+Asif!BB25+sumair!BB25 -> 0 | BK25: =Asghar!BF25+shahzad!BF25+Fahad!BF25+Asif!BF25+sumair!BF25 -> 0 | BL25: =Asghar!BJ25+shahzad!BJ25+Fahad!BJ25+Asif!BJ25+sumair!BJ25 -> 0 | BM25: =Asghar!BN25+shahzad!BN25+Fahad!BN25+Asif!BN25+sumair!BN25 -> 0 | BN25: =Asghar!BR25+shahzad!BR25+Fahad!BR25+Asif!BR25+sumair!BR25 -> 0 | BO25: =Asghar!BV25+shahzad!BV25+Fahad!BV25+Asif!BV25+sumair!BV25 -> 0 | BP25: =Asghar!BZ25+shahzad!BZ25+Fahad!BZ25+Asif!BZ25+sumair!BZ25 -> 0 | BQ25: =Asghar!CD25+shahzad!CD25+Fahad!CD25+Asif!CD25+sumair!CD25 -> 0 | BR25: =Asghar!CH25+shahzad!CH25+Fahad!CH25+Asif!CH25+sumair!CH25 -> 0 | BS25: =Asghar!CL25+shahzad!CL25+Fahad!CL25+Asif!CL25+sumair!CL25 -> 0 | BT25: =Asghar!CP25+shahzad!CP25+Fahad!CP25+Asif!CP25+sumair!CP25 -> 0 | BU25: =Asghar!CT25+shahzad!CT25+Fahad!CT25+Asif!CT25+sumair!CT25 -> 0 | BV25: =Asghar!CX25+shahzad!CX25+Fahad!CX25+Asif!CX25+sumair!CX25 -> 0 | BW25: =Asghar!DB25+shahzad!DB25+Fahad!DB25+Asif!DB25+sumair!DB25 -> 0 | BX25: =Asghar!DF25+shahzad!DF25+Fahad!DF25+Asif!DF25+sumair!DF25 -> 0 | BY25: =Asghar!DJ25+shahzad!DJ25+Fahad!DJ25+Asif!DJ25+sumair!DJ25 -> 0 | BZ25: =Asghar!DN25+shahzad!DN25+Fahad!DN25+Asif!DN25+sumair!DN25 -> 0 | CA25: =Asghar!DR25+shahzad!DR25+Fahad!DR25+Asif!DR25+sumair!DR25 -> 0 | CB25: =Asghar!DV25+shahzad!DV25+Fahad!DV25+Asif!DV25+sumair!DV25 -> 0 | CC25: =Asghar!DZ25+shahzad!DZ25+Fahad!DZ25+Asif!DZ25+sumair!DZ25 -> 0 | CD25: =SUM(AY25:CC25) -> 0 | CF25: =N25 -> 40.666667 | CG25: =AW25 -> 0 | CH25: =CG25+CF25 -> 40.666667 | CI25: =CD25 -> 0 | CJ25: =CH25-CI25 -> 40.666667
